index,image_path,text_path,error,traceback
396,dmd/multimodal/damaged_infrastructure/images/wreckedcar_2017-02-23_21-15-25.jpg,dmd/multimodal/damaged_infrastructure/text/wreckedcar_2017-02-23_21-15-25.txt,image file is truncated (0 bytes not processed),"Traceback (most recent call last):
  File ""/Users/sak/Desktop/demo_crisis_mmd/dmd_inference_ensemble_batched.py"", line 121, in <module>
    text_input, image_input, prep_time = load_and_preprocess(text_path, image_path)
  File ""/Users/sak/Desktop/demo_crisis_mmd/dmd_inference_ensemble_batched.py"", line 73, in load_and_preprocess
    img = image.load_img(image_file, target_size=(224, 224))
  File ""/Users/sak/Desktop/demo_crisis_mmd/crisis_mmd/lib/python3.10/site-packages/keras/src/utils/image_utils.py"", line 479, in load_img
    img = img.resize(width_height_tuple, resample)
  File ""/Users/sak/Desktop/demo_crisis_mmd/crisis_mmd/lib/python3.10/site-packages/PIL/Image.py"", line 2046, in resize
    self.load()
  File ""/Users/sak/Desktop/demo_crisis_mmd/crisis_mmd/lib/python3.10/site-packages/PIL/ImageFile.py"", line 251, in load
    raise OSError(
OSError: image file is truncated (0 bytes not processed)
"
549,dmd/multimodal/damaged_infrastructure/images/earthquake_2017-11-13_21-40-21.jpg,dmd/multimodal/damaged_infrastructure/text/earthquake_2017-11-13_21-40-21.txt,"Graph execution error:

Detected at node 'model/embedding/embedding_lookup' defined at (most recent call last):
    File ""/Users/sak/Desktop/demo_crisis_mmd/dmd_inference_ensemble_batched.py"", line 125, in <module>
      preds, inf_time = ensemble_predict(models, text_input, image_input)
    File ""/Users/sak/Desktop/demo_crisis_mmd/dmd_inference_ensemble_batched.py"", line 88, in ensemble_predict
      preds = [model.predict([image, text], verbose=0) for model in models]
    File ""/Users/sak/Desktop/demo_crisis_mmd/dmd_inference_ensemble_batched.py"", line 88, in <listcomp>
      preds = [model.predict([image, text], verbose=0) for model in models]
    File ""/Users/sak/Desktop/demo_crisis_mmd/crisis_mmd/lib/python3.10/site-packages/keras/src/utils/traceback_utils.py"", line 65, in error_handler
      return fn(*args, **kwargs)
    File ""/Users/sak/Desktop/demo_crisis_mmd/crisis_mmd/lib/python3.10/site-packages/keras/src/engine/training.py"", line 2554, in predict
      tmp_batch_outputs = self.predict_function(iterator)
    File ""/Users/sak/Desktop/demo_crisis_mmd/crisis_mmd/lib/python3.10/site-packages/keras/src/engine/training.py"", line 2341, in predict_function
      return step_function(self, iterator)
    File ""/Users/sak/Desktop/demo_crisis_mmd/crisis_mmd/lib/python3.10/site-packages/keras/src/engine/training.py"", line 2327, in step_function
      outputs = model.distribute_strategy.run(run_step, args=(data,))
    File ""/Users/sak/Desktop/demo_crisis_mmd/crisis_mmd/lib/python3.10/site-packages/keras/src/engine/training.py"", line 2315, in run_step
      outputs = model.predict_step(data)
    File ""/Users/sak/Desktop/demo_crisis_mmd/crisis_mmd/lib/python3.10/site-packages/keras/src/engine/training.py"", line 2283, in predict_step
      return self(x, training=False)
    File ""/Users/sak/Desktop/demo_crisis_mmd/crisis_mmd/lib/python3.10/site-packages/keras/src/utils/traceback_utils.py"", line 65, in error_handler
      return fn(*args, **kwargs)
    File ""/Users/sak/Desktop/demo_crisis_mmd/crisis_mmd/lib/python3.10/site-packages/keras/src/engine/training.py"", line 569, in __call__
      return super().__call__(*args, **kwargs)
    File ""/Users/sak/Desktop/demo_crisis_mmd/crisis_mmd/lib/python3.10/site-packages/keras/src/utils/traceback_utils.py"", line 65, in error_handler
      return fn(*args, **kwargs)
    File ""/Users/sak/Desktop/demo_crisis_mmd/crisis_mmd/lib/python3.10/site-packages/keras/src/engine/base_layer.py"", line 1150, in __call__
      outputs = call_fn(inputs, *args, **kwargs)
    File ""/Users/sak/Desktop/demo_crisis_mmd/crisis_mmd/lib/python3.10/site-packages/keras/src/utils/traceback_utils.py"", line 96, in error_handler
      return fn(*args, **kwargs)
    File ""/Users/sak/Desktop/demo_crisis_mmd/crisis_mmd/lib/python3.10/site-packages/keras/src/engine/functional.py"", line 512, in call
      return self._run_internal_graph(inputs, training=training, mask=mask)
    File ""/Users/sak/Desktop/demo_crisis_mmd/crisis_mmd/lib/python3.10/site-packages/keras/src/engine/functional.py"", line 669, in _run_internal_graph
      outputs = node.layer(*args, **kwargs)
    File ""/Users/sak/Desktop/demo_crisis_mmd/crisis_mmd/lib/python3.10/site-packages/keras/src/utils/traceback_utils.py"", line 65, in error_handler
      return fn(*args, **kwargs)
    File ""/Users/sak/Desktop/demo_crisis_mmd/crisis_mmd/lib/python3.10/site-packages/keras/src/engine/base_layer.py"", line 1150, in __call__
      outputs = call_fn(inputs, *args, **kwargs)
    File ""/Users/sak/Desktop/demo_crisis_mmd/crisis_mmd/lib/python3.10/site-packages/keras/src/utils/traceback_utils.py"", line 96, in error_handler
      return fn(*args, **kwargs)
    File ""/Users/sak/Desktop/demo_crisis_mmd/crisis_mmd/lib/python3.10/site-packages/keras/src/layers/core/embedding.py"", line 272, in call
      out = tf.nn.embedding_lookup(self.embeddings, inputs)
Node: 'model/embedding/embedding_lookup'
indices[0,10] = 170 is not in [0, 120)
	 [[{{node model/embedding/embedding_lookup}}]] [Op:__inference_predict_function_5943]","Traceback (most recent call last):
  File ""/Users/sak/Desktop/demo_crisis_mmd/dmd_inference_ensemble_batched.py"", line 125, in <module>
    preds, inf_time = ensemble_predict(models, text_input, image_input)
  File ""/Users/sak/Desktop/demo_crisis_mmd/dmd_inference_ensemble_batched.py"", line 88, in ensemble_predict
    preds = [model.predict([image, text], verbose=0) for model in models]
  File ""/Users/sak/Desktop/demo_crisis_mmd/dmd_inference_ensemble_batched.py"", line 88, in <listcomp>
    preds = [model.predict([image, text], verbose=0) for model in models]
  File ""/Users/sak/Desktop/demo_crisis_mmd/crisis_mmd/lib/python3.10/site-packages/keras/src/utils/traceback_utils.py"", line 70, in error_handler
    raise e.with_traceback(filtered_tb) from None
  File ""/Users/sak/Desktop/demo_crisis_mmd/crisis_mmd/lib/python3.10/site-packages/tensorflow/python/eager/execute.py"", line 53, in quick_execute
    tensors = pywrap_tfe.TFE_Py_Execute(ctx._handle, device_name, op_name,
tensorflow.python.framework.errors_impl.InvalidArgumentError: Graph execution error:

Detected at node 'model/embedding/embedding_lookup' defined at (most recent call last):
    File ""/Users/sak/Desktop/demo_crisis_mmd/dmd_inference_ensemble_batched.py"", line 125, in <module>
      preds, inf_time = ensemble_predict(models, text_input, image_input)
    File ""/Users/sak/Desktop/demo_crisis_mmd/dmd_inference_ensemble_batched.py"", line 88, in ensemble_predict
      preds = [model.predict([image, text], verbose=0) for model in models]
    File ""/Users/sak/Desktop/demo_crisis_mmd/dmd_inference_ensemble_batched.py"", line 88, in <listcomp>
      preds = [model.predict([image, text], verbose=0) for model in models]
    File ""/Users/sak/Desktop/demo_crisis_mmd/crisis_mmd/lib/python3.10/site-packages/keras/src/utils/traceback_utils.py"", line 65, in error_handler
      return fn(*args, **kwargs)
    File ""/Users/sak/Desktop/demo_crisis_mmd/crisis_mmd/lib/python3.10/site-packages/keras/src/engine/training.py"", line 2554, in predict
      tmp_batch_outputs = self.predict_function(iterator)
    File ""/Users/sak/Desktop/demo_crisis_mmd/crisis_mmd/lib/python3.10/site-packages/keras/src/engine/training.py"", line 2341, in predict_function
      return step_function(self, iterator)
    File ""/Users/sak/Desktop/demo_crisis_mmd/crisis_mmd/lib/python3.10/site-packages/keras/src/engine/training.py"", line 2327, in step_function
      outputs = model.distribute_strategy.run(run_step, args=(data,))
    File ""/Users/sak/Desktop/demo_crisis_mmd/crisis_mmd/lib/python3.10/site-packages/keras/src/engine/training.py"", line 2315, in run_step
      outputs = model.predict_step(data)
    File ""/Users/sak/Desktop/demo_crisis_mmd/crisis_mmd/lib/python3.10/site-packages/keras/src/engine/training.py"", line 2283, in predict_step
      return self(x, training=False)
    File ""/Users/sak/Desktop/demo_crisis_mmd/crisis_mmd/lib/python3.10/site-packages/keras/src/utils/traceback_utils.py"", line 65, in error_handler
      return fn(*args, **kwargs)
    File ""/Users/sak/Desktop/demo_crisis_mmd/crisis_mmd/lib/python3.10/site-packages/keras/src/engine/training.py"", line 569, in __call__
      return super().__call__(*args, **kwargs)
    File ""/Users/sak/Desktop/demo_crisis_mmd/crisis_mmd/lib/python3.10/site-packages/keras/src/utils/traceback_utils.py"", line 65, in error_handler
      return fn(*args, **kwargs)
    File ""/Users/sak/Desktop/demo_crisis_mmd/crisis_mmd/lib/python3.10/site-packages/keras/src/engine/base_layer.py"", line 1150, in __call__
      outputs = call_fn(inputs, *args, **kwargs)
    File ""/Users/sak/Desktop/demo_crisis_mmd/crisis_mmd/lib/python3.10/site-packages/keras/src/utils/traceback_utils.py"", line 96, in error_handler
      return fn(*args, **kwargs)
    File ""/Users/sak/Desktop/demo_crisis_mmd/crisis_mmd/lib/python3.10/site-packages/keras/src/engine/functional.py"", line 512, in call
      return self._run_internal_graph(inputs, training=training, mask=mask)
    File ""/Users/sak/Desktop/demo_crisis_mmd/crisis_mmd/lib/python3.10/site-packages/keras/src/engine/functional.py"", line 669, in _run_internal_graph
      outputs = node.layer(*args, **kwargs)
    File ""/Users/sak/Desktop/demo_crisis_mmd/crisis_mmd/lib/python3.10/site-packages/keras/src/utils/traceback_utils.py"", line 65, in error_handler
      return fn(*args, **kwargs)
    File ""/Users/sak/Desktop/demo_crisis_mmd/crisis_mmd/lib/python3.10/site-packages/keras/src/engine/base_layer.py"", line 1150, in __call__
      outputs = call_fn(inputs, *args, **kwargs)
    File ""/Users/sak/Desktop/demo_crisis_mmd/crisis_mmd/lib/python3.10/site-packages/keras/src/utils/traceback_utils.py"", line 96, in error_handler
      return fn(*args, **kwargs)
    File ""/Users/sak/Desktop/demo_crisis_mmd/crisis_mmd/lib/python3.10/site-packages/keras/src/layers/core/embedding.py"", line 272, in call
      out = tf.nn.embedding_lookup(self.embeddings, inputs)
Node: 'model/embedding/embedding_lookup'
indices[0,10] = 170 is not in [0, 120)
	 [[{{node model/embedding/embedding_lookup}}]] [Op:__inference_predict_function_5943]
"
2978,dmd/multimodal/non_damage/images/ad_2017-11-25_10-40-08.jpg,dmd/multimodal/non_damage/text/ad_2017-11-25_10-40-08.txt,"Graph execution error:

Detected at node 'model/embedding/embedding_lookup' defined at (most recent call last):
    File ""/Users/sak/Desktop/demo_crisis_mmd/dmd_inference_ensemble_batched.py"", line 125, in <module>
      preds, inf_time = ensemble_predict(models, text_input, image_input)
    File ""/Users/sak/Desktop/demo_crisis_mmd/dmd_inference_ensemble_batched.py"", line 88, in ensemble_predict
      preds = [model.predict([image, text], verbose=0) for model in models]
    File ""/Users/sak/Desktop/demo_crisis_mmd/dmd_inference_ensemble_batched.py"", line 88, in <listcomp>
      preds = [model.predict([image, text], verbose=0) for model in models]
    File ""/Users/sak/Desktop/demo_crisis_mmd/crisis_mmd/lib/python3.10/site-packages/keras/src/utils/traceback_utils.py"", line 65, in error_handler
      return fn(*args, **kwargs)
    File ""/Users/sak/Desktop/demo_crisis_mmd/crisis_mmd/lib/python3.10/site-packages/keras/src/engine/training.py"", line 2554, in predict
      tmp_batch_outputs = self.predict_function(iterator)
    File ""/Users/sak/Desktop/demo_crisis_mmd/crisis_mmd/lib/python3.10/site-packages/keras/src/engine/training.py"", line 2341, in predict_function
      return step_function(self, iterator)
    File ""/Users/sak/Desktop/demo_crisis_mmd/crisis_mmd/lib/python3.10/site-packages/keras/src/engine/training.py"", line 2327, in step_function
      outputs = model.distribute_strategy.run(run_step, args=(data,))
    File ""/Users/sak/Desktop/demo_crisis_mmd/crisis_mmd/lib/python3.10/site-packages/keras/src/engine/training.py"", line 2315, in run_step
      outputs = model.predict_step(data)
    File ""/Users/sak/Desktop/demo_crisis_mmd/crisis_mmd/lib/python3.10/site-packages/keras/src/engine/training.py"", line 2283, in predict_step
      return self(x, training=False)
    File ""/Users/sak/Desktop/demo_crisis_mmd/crisis_mmd/lib/python3.10/site-packages/keras/src/utils/traceback_utils.py"", line 65, in error_handler
      return fn(*args, **kwargs)
    File ""/Users/sak/Desktop/demo_crisis_mmd/crisis_mmd/lib/python3.10/site-packages/keras/src/engine/training.py"", line 569, in __call__
      return super().__call__(*args, **kwargs)
    File ""/Users/sak/Desktop/demo_crisis_mmd/crisis_mmd/lib/python3.10/site-packages/keras/src/utils/traceback_utils.py"", line 65, in error_handler
      return fn(*args, **kwargs)
    File ""/Users/sak/Desktop/demo_crisis_mmd/crisis_mmd/lib/python3.10/site-packages/keras/src/engine/base_layer.py"", line 1150, in __call__
      outputs = call_fn(inputs, *args, **kwargs)
    File ""/Users/sak/Desktop/demo_crisis_mmd/crisis_mmd/lib/python3.10/site-packages/keras/src/utils/traceback_utils.py"", line 96, in error_handler
      return fn(*args, **kwargs)
    File ""/Users/sak/Desktop/demo_crisis_mmd/crisis_mmd/lib/python3.10/site-packages/keras/src/engine/functional.py"", line 512, in call
      return self._run_internal_graph(inputs, training=training, mask=mask)
    File ""/Users/sak/Desktop/demo_crisis_mmd/crisis_mmd/lib/python3.10/site-packages/keras/src/engine/functional.py"", line 669, in _run_internal_graph
      outputs = node.layer(*args, **kwargs)
    File ""/Users/sak/Desktop/demo_crisis_mmd/crisis_mmd/lib/python3.10/site-packages/keras/src/utils/traceback_utils.py"", line 65, in error_handler
      return fn(*args, **kwargs)
    File ""/Users/sak/Desktop/demo_crisis_mmd/crisis_mmd/lib/python3.10/site-packages/keras/src/engine/base_layer.py"", line 1150, in __call__
      outputs = call_fn(inputs, *args, **kwargs)
    File ""/Users/sak/Desktop/demo_crisis_mmd/crisis_mmd/lib/python3.10/site-packages/keras/src/utils/traceback_utils.py"", line 96, in error_handler
      return fn(*args, **kwargs)
    File ""/Users/sak/Desktop/demo_crisis_mmd/crisis_mmd/lib/python3.10/site-packages/keras/src/layers/core/embedding.py"", line 272, in call
      out = tf.nn.embedding_lookup(self.embeddings, inputs)
Node: 'model/embedding/embedding_lookup'
indices[0,6] = 167 is not in [0, 120)
	 [[{{node model/embedding/embedding_lookup}}]] [Op:__inference_predict_function_5943]","Traceback (most recent call last):
  File ""/Users/sak/Desktop/demo_crisis_mmd/dmd_inference_ensemble_batched.py"", line 125, in <module>
    preds, inf_time = ensemble_predict(models, text_input, image_input)
  File ""/Users/sak/Desktop/demo_crisis_mmd/dmd_inference_ensemble_batched.py"", line 88, in ensemble_predict
    preds = [model.predict([image, text], verbose=0) for model in models]
  File ""/Users/sak/Desktop/demo_crisis_mmd/dmd_inference_ensemble_batched.py"", line 88, in <listcomp>
    preds = [model.predict([image, text], verbose=0) for model in models]
  File ""/Users/sak/Desktop/demo_crisis_mmd/crisis_mmd/lib/python3.10/site-packages/keras/src/utils/traceback_utils.py"", line 70, in error_handler
    raise e.with_traceback(filtered_tb) from None
  File ""/Users/sak/Desktop/demo_crisis_mmd/crisis_mmd/lib/python3.10/site-packages/tensorflow/python/eager/execute.py"", line 53, in quick_execute
    tensors = pywrap_tfe.TFE_Py_Execute(ctx._handle, device_name, op_name,
tensorflow.python.framework.errors_impl.InvalidArgumentError: Graph execution error:

Detected at node 'model/embedding/embedding_lookup' defined at (most recent call last):
    File ""/Users/sak/Desktop/demo_crisis_mmd/dmd_inference_ensemble_batched.py"", line 125, in <module>
      preds, inf_time = ensemble_predict(models, text_input, image_input)
    File ""/Users/sak/Desktop/demo_crisis_mmd/dmd_inference_ensemble_batched.py"", line 88, in ensemble_predict
      preds = [model.predict([image, text], verbose=0) for model in models]
    File ""/Users/sak/Desktop/demo_crisis_mmd/dmd_inference_ensemble_batched.py"", line 88, in <listcomp>
      preds = [model.predict([image, text], verbose=0) for model in models]
    File ""/Users/sak/Desktop/demo_crisis_mmd/crisis_mmd/lib/python3.10/site-packages/keras/src/utils/traceback_utils.py"", line 65, in error_handler
      return fn(*args, **kwargs)
    File ""/Users/sak/Desktop/demo_crisis_mmd/crisis_mmd/lib/python3.10/site-packages/keras/src/engine/training.py"", line 2554, in predict
      tmp_batch_outputs = self.predict_function(iterator)
    File ""/Users/sak/Desktop/demo_crisis_mmd/crisis_mmd/lib/python3.10/site-packages/keras/src/engine/training.py"", line 2341, in predict_function
      return step_function(self, iterator)
    File ""/Users/sak/Desktop/demo_crisis_mmd/crisis_mmd/lib/python3.10/site-packages/keras/src/engine/training.py"", line 2327, in step_function
      outputs = model.distribute_strategy.run(run_step, args=(data,))
    File ""/Users/sak/Desktop/demo_crisis_mmd/crisis_mmd/lib/python3.10/site-packages/keras/src/engine/training.py"", line 2315, in run_step
      outputs = model.predict_step(data)
    File ""/Users/sak/Desktop/demo_crisis_mmd/crisis_mmd/lib/python3.10/site-packages/keras/src/engine/training.py"", line 2283, in predict_step
      return self(x, training=False)
    File ""/Users/sak/Desktop/demo_crisis_mmd/crisis_mmd/lib/python3.10/site-packages/keras/src/utils/traceback_utils.py"", line 65, in error_handler
      return fn(*args, **kwargs)
    File ""/Users/sak/Desktop/demo_crisis_mmd/crisis_mmd/lib/python3.10/site-packages/keras/src/engine/training.py"", line 569, in __call__
      return super().__call__(*args, **kwargs)
    File ""/Users/sak/Desktop/demo_crisis_mmd/crisis_mmd/lib/python3.10/site-packages/keras/src/utils/traceback_utils.py"", line 65, in error_handler
      return fn(*args, **kwargs)
    File ""/Users/sak/Desktop/demo_crisis_mmd/crisis_mmd/lib/python3.10/site-packages/keras/src/engine/base_layer.py"", line 1150, in __call__
      outputs = call_fn(inputs, *args, **kwargs)
    File ""/Users/sak/Desktop/demo_crisis_mmd/crisis_mmd/lib/python3.10/site-packages/keras/src/utils/traceback_utils.py"", line 96, in error_handler
      return fn(*args, **kwargs)
    File ""/Users/sak/Desktop/demo_crisis_mmd/crisis_mmd/lib/python3.10/site-packages/keras/src/engine/functional.py"", line 512, in call
      return self._run_internal_graph(inputs, training=training, mask=mask)
    File ""/Users/sak/Desktop/demo_crisis_mmd/crisis_mmd/lib/python3.10/site-packages/keras/src/engine/functional.py"", line 669, in _run_internal_graph
      outputs = node.layer(*args, **kwargs)
    File ""/Users/sak/Desktop/demo_crisis_mmd/crisis_mmd/lib/python3.10/site-packages/keras/src/utils/traceback_utils.py"", line 65, in error_handler
      return fn(*args, **kwargs)
    File ""/Users/sak/Desktop/demo_crisis_mmd/crisis_mmd/lib/python3.10/site-packages/keras/src/engine/base_layer.py"", line 1150, in __call__
      outputs = call_fn(inputs, *args, **kwargs)
    File ""/Users/sak/Desktop/demo_crisis_mmd/crisis_mmd/lib/python3.10/site-packages/keras/src/utils/traceback_utils.py"", line 96, in error_handler
      return fn(*args, **kwargs)
    File ""/Users/sak/Desktop/demo_crisis_mmd/crisis_mmd/lib/python3.10/site-packages/keras/src/layers/core/embedding.py"", line 272, in call
      out = tf.nn.embedding_lookup(self.embeddings, inputs)
Node: 'model/embedding/embedding_lookup'
indices[0,6] = 167 is not in [0, 120)
	 [[{{node model/embedding/embedding_lookup}}]] [Op:__inference_predict_function_5943]
"
3087,dmd/multimodal/non_damage/images/ad_2017-11-25_07-09-06.jpg,dmd/multimodal/non_damage/text/ad_2017-11-25_07-09-06.txt,"Graph execution error:

Detected at node 'model/embedding/embedding_lookup' defined at (most recent call last):
    File ""/Users/sak/Desktop/demo_crisis_mmd/dmd_inference_ensemble_batched.py"", line 125, in <module>
      preds, inf_time = ensemble_predict(models, text_input, image_input)
    File ""/Users/sak/Desktop/demo_crisis_mmd/dmd_inference_ensemble_batched.py"", line 88, in ensemble_predict
      preds = [model.predict([image, text], verbose=0) for model in models]
    File ""/Users/sak/Desktop/demo_crisis_mmd/dmd_inference_ensemble_batched.py"", line 88, in <listcomp>
      preds = [model.predict([image, text], verbose=0) for model in models]
    File ""/Users/sak/Desktop/demo_crisis_mmd/crisis_mmd/lib/python3.10/site-packages/keras/src/utils/traceback_utils.py"", line 65, in error_handler
      return fn(*args, **kwargs)
    File ""/Users/sak/Desktop/demo_crisis_mmd/crisis_mmd/lib/python3.10/site-packages/keras/src/engine/training.py"", line 2554, in predict
      tmp_batch_outputs = self.predict_function(iterator)
    File ""/Users/sak/Desktop/demo_crisis_mmd/crisis_mmd/lib/python3.10/site-packages/keras/src/engine/training.py"", line 2341, in predict_function
      return step_function(self, iterator)
    File ""/Users/sak/Desktop/demo_crisis_mmd/crisis_mmd/lib/python3.10/site-packages/keras/src/engine/training.py"", line 2327, in step_function
      outputs = model.distribute_strategy.run(run_step, args=(data,))
    File ""/Users/sak/Desktop/demo_crisis_mmd/crisis_mmd/lib/python3.10/site-packages/keras/src/engine/training.py"", line 2315, in run_step
      outputs = model.predict_step(data)
    File ""/Users/sak/Desktop/demo_crisis_mmd/crisis_mmd/lib/python3.10/site-packages/keras/src/engine/training.py"", line 2283, in predict_step
      return self(x, training=False)
    File ""/Users/sak/Desktop/demo_crisis_mmd/crisis_mmd/lib/python3.10/site-packages/keras/src/utils/traceback_utils.py"", line 65, in error_handler
      return fn(*args, **kwargs)
    File ""/Users/sak/Desktop/demo_crisis_mmd/crisis_mmd/lib/python3.10/site-packages/keras/src/engine/training.py"", line 569, in __call__
      return super().__call__(*args, **kwargs)
    File ""/Users/sak/Desktop/demo_crisis_mmd/crisis_mmd/lib/python3.10/site-packages/keras/src/utils/traceback_utils.py"", line 65, in error_handler
      return fn(*args, **kwargs)
    File ""/Users/sak/Desktop/demo_crisis_mmd/crisis_mmd/lib/python3.10/site-packages/keras/src/engine/base_layer.py"", line 1150, in __call__
      outputs = call_fn(inputs, *args, **kwargs)
    File ""/Users/sak/Desktop/demo_crisis_mmd/crisis_mmd/lib/python3.10/site-packages/keras/src/utils/traceback_utils.py"", line 96, in error_handler
      return fn(*args, **kwargs)
    File ""/Users/sak/Desktop/demo_crisis_mmd/crisis_mmd/lib/python3.10/site-packages/keras/src/engine/functional.py"", line 512, in call
      return self._run_internal_graph(inputs, training=training, mask=mask)
    File ""/Users/sak/Desktop/demo_crisis_mmd/crisis_mmd/lib/python3.10/site-packages/keras/src/engine/functional.py"", line 669, in _run_internal_graph
      outputs = node.layer(*args, **kwargs)
    File ""/Users/sak/Desktop/demo_crisis_mmd/crisis_mmd/lib/python3.10/site-packages/keras/src/utils/traceback_utils.py"", line 65, in error_handler
      return fn(*args, **kwargs)
    File ""/Users/sak/Desktop/demo_crisis_mmd/crisis_mmd/lib/python3.10/site-packages/keras/src/engine/base_layer.py"", line 1150, in __call__
      outputs = call_fn(inputs, *args, **kwargs)
    File ""/Users/sak/Desktop/demo_crisis_mmd/crisis_mmd/lib/python3.10/site-packages/keras/src/utils/traceback_utils.py"", line 96, in error_handler
      return fn(*args, **kwargs)
    File ""/Users/sak/Desktop/demo_crisis_mmd/crisis_mmd/lib/python3.10/site-packages/keras/src/layers/core/embedding.py"", line 272, in call
      out = tf.nn.embedding_lookup(self.embeddings, inputs)
Node: 'model/embedding/embedding_lookup'
indices[0,16] = 167 is not in [0, 120)
	 [[{{node model/embedding/embedding_lookup}}]] [Op:__inference_predict_function_5943]","Traceback (most recent call last):
  File ""/Users/sak/Desktop/demo_crisis_mmd/dmd_inference_ensemble_batched.py"", line 125, in <module>
    preds, inf_time = ensemble_predict(models, text_input, image_input)
  File ""/Users/sak/Desktop/demo_crisis_mmd/dmd_inference_ensemble_batched.py"", line 88, in ensemble_predict
    preds = [model.predict([image, text], verbose=0) for model in models]
  File ""/Users/sak/Desktop/demo_crisis_mmd/dmd_inference_ensemble_batched.py"", line 88, in <listcomp>
    preds = [model.predict([image, text], verbose=0) for model in models]
  File ""/Users/sak/Desktop/demo_crisis_mmd/crisis_mmd/lib/python3.10/site-packages/keras/src/utils/traceback_utils.py"", line 70, in error_handler
    raise e.with_traceback(filtered_tb) from None
  File ""/Users/sak/Desktop/demo_crisis_mmd/crisis_mmd/lib/python3.10/site-packages/tensorflow/python/eager/execute.py"", line 53, in quick_execute
    tensors = pywrap_tfe.TFE_Py_Execute(ctx._handle, device_name, op_name,
tensorflow.python.framework.errors_impl.InvalidArgumentError: Graph execution error:

Detected at node 'model/embedding/embedding_lookup' defined at (most recent call last):
    File ""/Users/sak/Desktop/demo_crisis_mmd/dmd_inference_ensemble_batched.py"", line 125, in <module>
      preds, inf_time = ensemble_predict(models, text_input, image_input)
    File ""/Users/sak/Desktop/demo_crisis_mmd/dmd_inference_ensemble_batched.py"", line 88, in ensemble_predict
      preds = [model.predict([image, text], verbose=0) for model in models]
    File ""/Users/sak/Desktop/demo_crisis_mmd/dmd_inference_ensemble_batched.py"", line 88, in <listcomp>
      preds = [model.predict([image, text], verbose=0) for model in models]
    File ""/Users/sak/Desktop/demo_crisis_mmd/crisis_mmd/lib/python3.10/site-packages/keras/src/utils/traceback_utils.py"", line 65, in error_handler
      return fn(*args, **kwargs)
    File ""/Users/sak/Desktop/demo_crisis_mmd/crisis_mmd/lib/python3.10/site-packages/keras/src/engine/training.py"", line 2554, in predict
      tmp_batch_outputs = self.predict_function(iterator)
    File ""/Users/sak/Desktop/demo_crisis_mmd/crisis_mmd/lib/python3.10/site-packages/keras/src/engine/training.py"", line 2341, in predict_function
      return step_function(self, iterator)
    File ""/Users/sak/Desktop/demo_crisis_mmd/crisis_mmd/lib/python3.10/site-packages/keras/src/engine/training.py"", line 2327, in step_function
      outputs = model.distribute_strategy.run(run_step, args=(data,))
    File ""/Users/sak/Desktop/demo_crisis_mmd/crisis_mmd/lib/python3.10/site-packages/keras/src/engine/training.py"", line 2315, in run_step
      outputs = model.predict_step(data)
    File ""/Users/sak/Desktop/demo_crisis_mmd/crisis_mmd/lib/python3.10/site-packages/keras/src/engine/training.py"", line 2283, in predict_step
      return self(x, training=False)
    File ""/Users/sak/Desktop/demo_crisis_mmd/crisis_mmd/lib/python3.10/site-packages/keras/src/utils/traceback_utils.py"", line 65, in error_handler
      return fn(*args, **kwargs)
    File ""/Users/sak/Desktop/demo_crisis_mmd/crisis_mmd/lib/python3.10/site-packages/keras/src/engine/training.py"", line 569, in __call__
      return super().__call__(*args, **kwargs)
    File ""/Users/sak/Desktop/demo_crisis_mmd/crisis_mmd/lib/python3.10/site-packages/keras/src/utils/traceback_utils.py"", line 65, in error_handler
      return fn(*args, **kwargs)
    File ""/Users/sak/Desktop/demo_crisis_mmd/crisis_mmd/lib/python3.10/site-packages/keras/src/engine/base_layer.py"", line 1150, in __call__
      outputs = call_fn(inputs, *args, **kwargs)
    File ""/Users/sak/Desktop/demo_crisis_mmd/crisis_mmd/lib/python3.10/site-packages/keras/src/utils/traceback_utils.py"", line 96, in error_handler
      return fn(*args, **kwargs)
    File ""/Users/sak/Desktop/demo_crisis_mmd/crisis_mmd/lib/python3.10/site-packages/keras/src/engine/functional.py"", line 512, in call
      return self._run_internal_graph(inputs, training=training, mask=mask)
    File ""/Users/sak/Desktop/demo_crisis_mmd/crisis_mmd/lib/python3.10/site-packages/keras/src/engine/functional.py"", line 669, in _run_internal_graph
      outputs = node.layer(*args, **kwargs)
    File ""/Users/sak/Desktop/demo_crisis_mmd/crisis_mmd/lib/python3.10/site-packages/keras/src/utils/traceback_utils.py"", line 65, in error_handler
      return fn(*args, **kwargs)
    File ""/Users/sak/Desktop/demo_crisis_mmd/crisis_mmd/lib/python3.10/site-packages/keras/src/engine/base_layer.py"", line 1150, in __call__
      outputs = call_fn(inputs, *args, **kwargs)
    File ""/Users/sak/Desktop/demo_crisis_mmd/crisis_mmd/lib/python3.10/site-packages/keras/src/utils/traceback_utils.py"", line 96, in error_handler
      return fn(*args, **kwargs)
    File ""/Users/sak/Desktop/demo_crisis_mmd/crisis_mmd/lib/python3.10/site-packages/keras/src/layers/core/embedding.py"", line 272, in call
      out = tf.nn.embedding_lookup(self.embeddings, inputs)
Node: 'model/embedding/embedding_lookup'
indices[0,16] = 167 is not in [0, 120)
	 [[{{node model/embedding/embedding_lookup}}]] [Op:__inference_predict_function_5943]
"
3426,dmd/multimodal/non_damage/images/ad_2017-11-25_04-29-51.jpg,dmd/multimodal/non_damage/text/ad_2017-11-25_04-29-51.txt,"Graph execution error:

Detected at node 'model/embedding/embedding_lookup' defined at (most recent call last):
    File ""/Users/sak/Desktop/demo_crisis_mmd/dmd_inference_ensemble_batched.py"", line 125, in <module>
      preds, inf_time = ensemble_predict(models, text_input, image_input)
    File ""/Users/sak/Desktop/demo_crisis_mmd/dmd_inference_ensemble_batched.py"", line 88, in ensemble_predict
      preds = [model.predict([image, text], verbose=0) for model in models]
    File ""/Users/sak/Desktop/demo_crisis_mmd/dmd_inference_ensemble_batched.py"", line 88, in <listcomp>
      preds = [model.predict([image, text], verbose=0) for model in models]
    File ""/Users/sak/Desktop/demo_crisis_mmd/crisis_mmd/lib/python3.10/site-packages/keras/src/utils/traceback_utils.py"", line 65, in error_handler
      return fn(*args, **kwargs)
    File ""/Users/sak/Desktop/demo_crisis_mmd/crisis_mmd/lib/python3.10/site-packages/keras/src/engine/training.py"", line 2554, in predict
      tmp_batch_outputs = self.predict_function(iterator)
    File ""/Users/sak/Desktop/demo_crisis_mmd/crisis_mmd/lib/python3.10/site-packages/keras/src/engine/training.py"", line 2341, in predict_function
      return step_function(self, iterator)
    File ""/Users/sak/Desktop/demo_crisis_mmd/crisis_mmd/lib/python3.10/site-packages/keras/src/engine/training.py"", line 2327, in step_function
      outputs = model.distribute_strategy.run(run_step, args=(data,))
    File ""/Users/sak/Desktop/demo_crisis_mmd/crisis_mmd/lib/python3.10/site-packages/keras/src/engine/training.py"", line 2315, in run_step
      outputs = model.predict_step(data)
    File ""/Users/sak/Desktop/demo_crisis_mmd/crisis_mmd/lib/python3.10/site-packages/keras/src/engine/training.py"", line 2283, in predict_step
      return self(x, training=False)
    File ""/Users/sak/Desktop/demo_crisis_mmd/crisis_mmd/lib/python3.10/site-packages/keras/src/utils/traceback_utils.py"", line 65, in error_handler
      return fn(*args, **kwargs)
    File ""/Users/sak/Desktop/demo_crisis_mmd/crisis_mmd/lib/python3.10/site-packages/keras/src/engine/training.py"", line 569, in __call__
      return super().__call__(*args, **kwargs)
    File ""/Users/sak/Desktop/demo_crisis_mmd/crisis_mmd/lib/python3.10/site-packages/keras/src/utils/traceback_utils.py"", line 65, in error_handler
      return fn(*args, **kwargs)
    File ""/Users/sak/Desktop/demo_crisis_mmd/crisis_mmd/lib/python3.10/site-packages/keras/src/engine/base_layer.py"", line 1150, in __call__
      outputs = call_fn(inputs, *args, **kwargs)
    File ""/Users/sak/Desktop/demo_crisis_mmd/crisis_mmd/lib/python3.10/site-packages/keras/src/utils/traceback_utils.py"", line 96, in error_handler
      return fn(*args, **kwargs)
    File ""/Users/sak/Desktop/demo_crisis_mmd/crisis_mmd/lib/python3.10/site-packages/keras/src/engine/functional.py"", line 512, in call
      return self._run_internal_graph(inputs, training=training, mask=mask)
    File ""/Users/sak/Desktop/demo_crisis_mmd/crisis_mmd/lib/python3.10/site-packages/keras/src/engine/functional.py"", line 669, in _run_internal_graph
      outputs = node.layer(*args, **kwargs)
    File ""/Users/sak/Desktop/demo_crisis_mmd/crisis_mmd/lib/python3.10/site-packages/keras/src/utils/traceback_utils.py"", line 65, in error_handler
      return fn(*args, **kwargs)
    File ""/Users/sak/Desktop/demo_crisis_mmd/crisis_mmd/lib/python3.10/site-packages/keras/src/engine/base_layer.py"", line 1150, in __call__
      outputs = call_fn(inputs, *args, **kwargs)
    File ""/Users/sak/Desktop/demo_crisis_mmd/crisis_mmd/lib/python3.10/site-packages/keras/src/utils/traceback_utils.py"", line 96, in error_handler
      return fn(*args, **kwargs)
    File ""/Users/sak/Desktop/demo_crisis_mmd/crisis_mmd/lib/python3.10/site-packages/keras/src/layers/core/embedding.py"", line 272, in call
      out = tf.nn.embedding_lookup(self.embeddings, inputs)
Node: 'model/embedding/embedding_lookup'
indices[0,21] = 167 is not in [0, 120)
	 [[{{node model/embedding/embedding_lookup}}]] [Op:__inference_predict_function_5943]","Traceback (most recent call last):
  File ""/Users/sak/Desktop/demo_crisis_mmd/dmd_inference_ensemble_batched.py"", line 125, in <module>
    preds, inf_time = ensemble_predict(models, text_input, image_input)
  File ""/Users/sak/Desktop/demo_crisis_mmd/dmd_inference_ensemble_batched.py"", line 88, in ensemble_predict
    preds = [model.predict([image, text], verbose=0) for model in models]
  File ""/Users/sak/Desktop/demo_crisis_mmd/dmd_inference_ensemble_batched.py"", line 88, in <listcomp>
    preds = [model.predict([image, text], verbose=0) for model in models]
  File ""/Users/sak/Desktop/demo_crisis_mmd/crisis_mmd/lib/python3.10/site-packages/keras/src/utils/traceback_utils.py"", line 70, in error_handler
    raise e.with_traceback(filtered_tb) from None
  File ""/Users/sak/Desktop/demo_crisis_mmd/crisis_mmd/lib/python3.10/site-packages/tensorflow/python/eager/execute.py"", line 53, in quick_execute
    tensors = pywrap_tfe.TFE_Py_Execute(ctx._handle, device_name, op_name,
tensorflow.python.framework.errors_impl.InvalidArgumentError: Graph execution error:

Detected at node 'model/embedding/embedding_lookup' defined at (most recent call last):
    File ""/Users/sak/Desktop/demo_crisis_mmd/dmd_inference_ensemble_batched.py"", line 125, in <module>
      preds, inf_time = ensemble_predict(models, text_input, image_input)
    File ""/Users/sak/Desktop/demo_crisis_mmd/dmd_inference_ensemble_batched.py"", line 88, in ensemble_predict
      preds = [model.predict([image, text], verbose=0) for model in models]
    File ""/Users/sak/Desktop/demo_crisis_mmd/dmd_inference_ensemble_batched.py"", line 88, in <listcomp>
      preds = [model.predict([image, text], verbose=0) for model in models]
    File ""/Users/sak/Desktop/demo_crisis_mmd/crisis_mmd/lib/python3.10/site-packages/keras/src/utils/traceback_utils.py"", line 65, in error_handler
      return fn(*args, **kwargs)
    File ""/Users/sak/Desktop/demo_crisis_mmd/crisis_mmd/lib/python3.10/site-packages/keras/src/engine/training.py"", line 2554, in predict
      tmp_batch_outputs = self.predict_function(iterator)
    File ""/Users/sak/Desktop/demo_crisis_mmd/crisis_mmd/lib/python3.10/site-packages/keras/src/engine/training.py"", line 2341, in predict_function
      return step_function(self, iterator)
    File ""/Users/sak/Desktop/demo_crisis_mmd/crisis_mmd/lib/python3.10/site-packages/keras/src/engine/training.py"", line 2327, in step_function
      outputs = model.distribute_strategy.run(run_step, args=(data,))
    File ""/Users/sak/Desktop/demo_crisis_mmd/crisis_mmd/lib/python3.10/site-packages/keras/src/engine/training.py"", line 2315, in run_step
      outputs = model.predict_step(data)
    File ""/Users/sak/Desktop/demo_crisis_mmd/crisis_mmd/lib/python3.10/site-packages/keras/src/engine/training.py"", line 2283, in predict_step
      return self(x, training=False)
    File ""/Users/sak/Desktop/demo_crisis_mmd/crisis_mmd/lib/python3.10/site-packages/keras/src/utils/traceback_utils.py"", line 65, in error_handler
      return fn(*args, **kwargs)
    File ""/Users/sak/Desktop/demo_crisis_mmd/crisis_mmd/lib/python3.10/site-packages/keras/src/engine/training.py"", line 569, in __call__
      return super().__call__(*args, **kwargs)
    File ""/Users/sak/Desktop/demo_crisis_mmd/crisis_mmd/lib/python3.10/site-packages/keras/src/utils/traceback_utils.py"", line 65, in error_handler
      return fn(*args, **kwargs)
    File ""/Users/sak/Desktop/demo_crisis_mmd/crisis_mmd/lib/python3.10/site-packages/keras/src/engine/base_layer.py"", line 1150, in __call__
      outputs = call_fn(inputs, *args, **kwargs)
    File ""/Users/sak/Desktop/demo_crisis_mmd/crisis_mmd/lib/python3.10/site-packages/keras/src/utils/traceback_utils.py"", line 96, in error_handler
      return fn(*args, **kwargs)
    File ""/Users/sak/Desktop/demo_crisis_mmd/crisis_mmd/lib/python3.10/site-packages/keras/src/engine/functional.py"", line 512, in call
      return self._run_internal_graph(inputs, training=training, mask=mask)
    File ""/Users/sak/Desktop/demo_crisis_mmd/crisis_mmd/lib/python3.10/site-packages/keras/src/engine/functional.py"", line 669, in _run_internal_graph
      outputs = node.layer(*args, **kwargs)
    File ""/Users/sak/Desktop/demo_crisis_mmd/crisis_mmd/lib/python3.10/site-packages/keras/src/utils/traceback_utils.py"", line 65, in error_handler
      return fn(*args, **kwargs)
    File ""/Users/sak/Desktop/demo_crisis_mmd/crisis_mmd/lib/python3.10/site-packages/keras/src/engine/base_layer.py"", line 1150, in __call__
      outputs = call_fn(inputs, *args, **kwargs)
    File ""/Users/sak/Desktop/demo_crisis_mmd/crisis_mmd/lib/python3.10/site-packages/keras/src/utils/traceback_utils.py"", line 96, in error_handler
      return fn(*args, **kwargs)
    File ""/Users/sak/Desktop/demo_crisis_mmd/crisis_mmd/lib/python3.10/site-packages/keras/src/layers/core/embedding.py"", line 272, in call
      out = tf.nn.embedding_lookup(self.embeddings, inputs)
Node: 'model/embedding/embedding_lookup'
indices[0,21] = 167 is not in [0, 120)
	 [[{{node model/embedding/embedding_lookup}}]] [Op:__inference_predict_function_5943]
"
3580,dmd/multimodal/non_damage/images/ad_2017-11-25_11-33-18.jpg,dmd/multimodal/non_damage/text/ad_2017-11-25_11-33-18.txt,"Graph execution error:

Detected at node 'model/embedding/embedding_lookup' defined at (most recent call last):
    File ""/Users/sak/Desktop/demo_crisis_mmd/dmd_inference_ensemble_batched.py"", line 125, in <module>
      preds, inf_time = ensemble_predict(models, text_input, image_input)
    File ""/Users/sak/Desktop/demo_crisis_mmd/dmd_inference_ensemble_batched.py"", line 88, in ensemble_predict
      preds = [model.predict([image, text], verbose=0) for model in models]
    File ""/Users/sak/Desktop/demo_crisis_mmd/dmd_inference_ensemble_batched.py"", line 88, in <listcomp>
      preds = [model.predict([image, text], verbose=0) for model in models]
    File ""/Users/sak/Desktop/demo_crisis_mmd/crisis_mmd/lib/python3.10/site-packages/keras/src/utils/traceback_utils.py"", line 65, in error_handler
      return fn(*args, **kwargs)
    File ""/Users/sak/Desktop/demo_crisis_mmd/crisis_mmd/lib/python3.10/site-packages/keras/src/engine/training.py"", line 2554, in predict
      tmp_batch_outputs = self.predict_function(iterator)
    File ""/Users/sak/Desktop/demo_crisis_mmd/crisis_mmd/lib/python3.10/site-packages/keras/src/engine/training.py"", line 2341, in predict_function
      return step_function(self, iterator)
    File ""/Users/sak/Desktop/demo_crisis_mmd/crisis_mmd/lib/python3.10/site-packages/keras/src/engine/training.py"", line 2327, in step_function
      outputs = model.distribute_strategy.run(run_step, args=(data,))
    File ""/Users/sak/Desktop/demo_crisis_mmd/crisis_mmd/lib/python3.10/site-packages/keras/src/engine/training.py"", line 2315, in run_step
      outputs = model.predict_step(data)
    File ""/Users/sak/Desktop/demo_crisis_mmd/crisis_mmd/lib/python3.10/site-packages/keras/src/engine/training.py"", line 2283, in predict_step
      return self(x, training=False)
    File ""/Users/sak/Desktop/demo_crisis_mmd/crisis_mmd/lib/python3.10/site-packages/keras/src/utils/traceback_utils.py"", line 65, in error_handler
      return fn(*args, **kwargs)
    File ""/Users/sak/Desktop/demo_crisis_mmd/crisis_mmd/lib/python3.10/site-packages/keras/src/engine/training.py"", line 569, in __call__
      return super().__call__(*args, **kwargs)
    File ""/Users/sak/Desktop/demo_crisis_mmd/crisis_mmd/lib/python3.10/site-packages/keras/src/utils/traceback_utils.py"", line 65, in error_handler
      return fn(*args, **kwargs)
    File ""/Users/sak/Desktop/demo_crisis_mmd/crisis_mmd/lib/python3.10/site-packages/keras/src/engine/base_layer.py"", line 1150, in __call__
      outputs = call_fn(inputs, *args, **kwargs)
    File ""/Users/sak/Desktop/demo_crisis_mmd/crisis_mmd/lib/python3.10/site-packages/keras/src/utils/traceback_utils.py"", line 96, in error_handler
      return fn(*args, **kwargs)
    File ""/Users/sak/Desktop/demo_crisis_mmd/crisis_mmd/lib/python3.10/site-packages/keras/src/engine/functional.py"", line 512, in call
      return self._run_internal_graph(inputs, training=training, mask=mask)
    File ""/Users/sak/Desktop/demo_crisis_mmd/crisis_mmd/lib/python3.10/site-packages/keras/src/engine/functional.py"", line 669, in _run_internal_graph
      outputs = node.layer(*args, **kwargs)
    File ""/Users/sak/Desktop/demo_crisis_mmd/crisis_mmd/lib/python3.10/site-packages/keras/src/utils/traceback_utils.py"", line 65, in error_handler
      return fn(*args, **kwargs)
    File ""/Users/sak/Desktop/demo_crisis_mmd/crisis_mmd/lib/python3.10/site-packages/keras/src/engine/base_layer.py"", line 1150, in __call__
      outputs = call_fn(inputs, *args, **kwargs)
    File ""/Users/sak/Desktop/demo_crisis_mmd/crisis_mmd/lib/python3.10/site-packages/keras/src/utils/traceback_utils.py"", line 96, in error_handler
      return fn(*args, **kwargs)
    File ""/Users/sak/Desktop/demo_crisis_mmd/crisis_mmd/lib/python3.10/site-packages/keras/src/layers/core/embedding.py"", line 272, in call
      out = tf.nn.embedding_lookup(self.embeddings, inputs)
Node: 'model/embedding/embedding_lookup'
indices[0,9] = 167 is not in [0, 120)
	 [[{{node model/embedding/embedding_lookup}}]] [Op:__inference_predict_function_5943]","Traceback (most recent call last):
  File ""/Users/sak/Desktop/demo_crisis_mmd/dmd_inference_ensemble_batched.py"", line 125, in <module>
    preds, inf_time = ensemble_predict(models, text_input, image_input)
  File ""/Users/sak/Desktop/demo_crisis_mmd/dmd_inference_ensemble_batched.py"", line 88, in ensemble_predict
    preds = [model.predict([image, text], verbose=0) for model in models]
  File ""/Users/sak/Desktop/demo_crisis_mmd/dmd_inference_ensemble_batched.py"", line 88, in <listcomp>
    preds = [model.predict([image, text], verbose=0) for model in models]
  File ""/Users/sak/Desktop/demo_crisis_mmd/crisis_mmd/lib/python3.10/site-packages/keras/src/utils/traceback_utils.py"", line 70, in error_handler
    raise e.with_traceback(filtered_tb) from None
  File ""/Users/sak/Desktop/demo_crisis_mmd/crisis_mmd/lib/python3.10/site-packages/tensorflow/python/eager/execute.py"", line 53, in quick_execute
    tensors = pywrap_tfe.TFE_Py_Execute(ctx._handle, device_name, op_name,
tensorflow.python.framework.errors_impl.InvalidArgumentError: Graph execution error:

Detected at node 'model/embedding/embedding_lookup' defined at (most recent call last):
    File ""/Users/sak/Desktop/demo_crisis_mmd/dmd_inference_ensemble_batched.py"", line 125, in <module>
      preds, inf_time = ensemble_predict(models, text_input, image_input)
    File ""/Users/sak/Desktop/demo_crisis_mmd/dmd_inference_ensemble_batched.py"", line 88, in ensemble_predict
      preds = [model.predict([image, text], verbose=0) for model in models]
    File ""/Users/sak/Desktop/demo_crisis_mmd/dmd_inference_ensemble_batched.py"", line 88, in <listcomp>
      preds = [model.predict([image, text], verbose=0) for model in models]
    File ""/Users/sak/Desktop/demo_crisis_mmd/crisis_mmd/lib/python3.10/site-packages/keras/src/utils/traceback_utils.py"", line 65, in error_handler
      return fn(*args, **kwargs)
    File ""/Users/sak/Desktop/demo_crisis_mmd/crisis_mmd/lib/python3.10/site-packages/keras/src/engine/training.py"", line 2554, in predict
      tmp_batch_outputs = self.predict_function(iterator)
    File ""/Users/sak/Desktop/demo_crisis_mmd/crisis_mmd/lib/python3.10/site-packages/keras/src/engine/training.py"", line 2341, in predict_function
      return step_function(self, iterator)
    File ""/Users/sak/Desktop/demo_crisis_mmd/crisis_mmd/lib/python3.10/site-packages/keras/src/engine/training.py"", line 2327, in step_function
      outputs = model.distribute_strategy.run(run_step, args=(data,))
    File ""/Users/sak/Desktop/demo_crisis_mmd/crisis_mmd/lib/python3.10/site-packages/keras/src/engine/training.py"", line 2315, in run_step
      outputs = model.predict_step(data)
    File ""/Users/sak/Desktop/demo_crisis_mmd/crisis_mmd/lib/python3.10/site-packages/keras/src/engine/training.py"", line 2283, in predict_step
      return self(x, training=False)
    File ""/Users/sak/Desktop/demo_crisis_mmd/crisis_mmd/lib/python3.10/site-packages/keras/src/utils/traceback_utils.py"", line 65, in error_handler
      return fn(*args, **kwargs)
    File ""/Users/sak/Desktop/demo_crisis_mmd/crisis_mmd/lib/python3.10/site-packages/keras/src/engine/training.py"", line 569, in __call__
      return super().__call__(*args, **kwargs)
    File ""/Users/sak/Desktop/demo_crisis_mmd/crisis_mmd/lib/python3.10/site-packages/keras/src/utils/traceback_utils.py"", line 65, in error_handler
      return fn(*args, **kwargs)
    File ""/Users/sak/Desktop/demo_crisis_mmd/crisis_mmd/lib/python3.10/site-packages/keras/src/engine/base_layer.py"", line 1150, in __call__
      outputs = call_fn(inputs, *args, **kwargs)
    File ""/Users/sak/Desktop/demo_crisis_mmd/crisis_mmd/lib/python3.10/site-packages/keras/src/utils/traceback_utils.py"", line 96, in error_handler
      return fn(*args, **kwargs)
    File ""/Users/sak/Desktop/demo_crisis_mmd/crisis_mmd/lib/python3.10/site-packages/keras/src/engine/functional.py"", line 512, in call
      return self._run_internal_graph(inputs, training=training, mask=mask)
    File ""/Users/sak/Desktop/demo_crisis_mmd/crisis_mmd/lib/python3.10/site-packages/keras/src/engine/functional.py"", line 669, in _run_internal_graph
      outputs = node.layer(*args, **kwargs)
    File ""/Users/sak/Desktop/demo_crisis_mmd/crisis_mmd/lib/python3.10/site-packages/keras/src/utils/traceback_utils.py"", line 65, in error_handler
      return fn(*args, **kwargs)
    File ""/Users/sak/Desktop/demo_crisis_mmd/crisis_mmd/lib/python3.10/site-packages/keras/src/engine/base_layer.py"", line 1150, in __call__
      outputs = call_fn(inputs, *args, **kwargs)
    File ""/Users/sak/Desktop/demo_crisis_mmd/crisis_mmd/lib/python3.10/site-packages/keras/src/utils/traceback_utils.py"", line 96, in error_handler
      return fn(*args, **kwargs)
    File ""/Users/sak/Desktop/demo_crisis_mmd/crisis_mmd/lib/python3.10/site-packages/keras/src/layers/core/embedding.py"", line 272, in call
      out = tf.nn.embedding_lookup(self.embeddings, inputs)
Node: 'model/embedding/embedding_lookup'
indices[0,9] = 167 is not in [0, 120)
	 [[{{node model/embedding/embedding_lookup}}]] [Op:__inference_predict_function_5943]
"
3981,dmd/multimodal/non_damage/images/ad_2017-11-25_11-11-42.jpg,dmd/multimodal/non_damage/text/ad_2017-11-25_11-11-42.txt,"Graph execution error:

Detected at node 'model/embedding/embedding_lookup' defined at (most recent call last):
    File ""/Users/sak/Desktop/demo_crisis_mmd/dmd_inference_ensemble_batched.py"", line 125, in <module>
      preds, inf_time = ensemble_predict(models, text_input, image_input)
    File ""/Users/sak/Desktop/demo_crisis_mmd/dmd_inference_ensemble_batched.py"", line 88, in ensemble_predict
      preds = [model.predict([image, text], verbose=0) for model in models]
    File ""/Users/sak/Desktop/demo_crisis_mmd/dmd_inference_ensemble_batched.py"", line 88, in <listcomp>
      preds = [model.predict([image, text], verbose=0) for model in models]
    File ""/Users/sak/Desktop/demo_crisis_mmd/crisis_mmd/lib/python3.10/site-packages/keras/src/utils/traceback_utils.py"", line 65, in error_handler
      return fn(*args, **kwargs)
    File ""/Users/sak/Desktop/demo_crisis_mmd/crisis_mmd/lib/python3.10/site-packages/keras/src/engine/training.py"", line 2554, in predict
      tmp_batch_outputs = self.predict_function(iterator)
    File ""/Users/sak/Desktop/demo_crisis_mmd/crisis_mmd/lib/python3.10/site-packages/keras/src/engine/training.py"", line 2341, in predict_function
      return step_function(self, iterator)
    File ""/Users/sak/Desktop/demo_crisis_mmd/crisis_mmd/lib/python3.10/site-packages/keras/src/engine/training.py"", line 2327, in step_function
      outputs = model.distribute_strategy.run(run_step, args=(data,))
    File ""/Users/sak/Desktop/demo_crisis_mmd/crisis_mmd/lib/python3.10/site-packages/keras/src/engine/training.py"", line 2315, in run_step
      outputs = model.predict_step(data)
    File ""/Users/sak/Desktop/demo_crisis_mmd/crisis_mmd/lib/python3.10/site-packages/keras/src/engine/training.py"", line 2283, in predict_step
      return self(x, training=False)
    File ""/Users/sak/Desktop/demo_crisis_mmd/crisis_mmd/lib/python3.10/site-packages/keras/src/utils/traceback_utils.py"", line 65, in error_handler
      return fn(*args, **kwargs)
    File ""/Users/sak/Desktop/demo_crisis_mmd/crisis_mmd/lib/python3.10/site-packages/keras/src/engine/training.py"", line 569, in __call__
      return super().__call__(*args, **kwargs)
    File ""/Users/sak/Desktop/demo_crisis_mmd/crisis_mmd/lib/python3.10/site-packages/keras/src/utils/traceback_utils.py"", line 65, in error_handler
      return fn(*args, **kwargs)
    File ""/Users/sak/Desktop/demo_crisis_mmd/crisis_mmd/lib/python3.10/site-packages/keras/src/engine/base_layer.py"", line 1150, in __call__
      outputs = call_fn(inputs, *args, **kwargs)
    File ""/Users/sak/Desktop/demo_crisis_mmd/crisis_mmd/lib/python3.10/site-packages/keras/src/utils/traceback_utils.py"", line 96, in error_handler
      return fn(*args, **kwargs)
    File ""/Users/sak/Desktop/demo_crisis_mmd/crisis_mmd/lib/python3.10/site-packages/keras/src/engine/functional.py"", line 512, in call
      return self._run_internal_graph(inputs, training=training, mask=mask)
    File ""/Users/sak/Desktop/demo_crisis_mmd/crisis_mmd/lib/python3.10/site-packages/keras/src/engine/functional.py"", line 669, in _run_internal_graph
      outputs = node.layer(*args, **kwargs)
    File ""/Users/sak/Desktop/demo_crisis_mmd/crisis_mmd/lib/python3.10/site-packages/keras/src/utils/traceback_utils.py"", line 65, in error_handler
      return fn(*args, **kwargs)
    File ""/Users/sak/Desktop/demo_crisis_mmd/crisis_mmd/lib/python3.10/site-packages/keras/src/engine/base_layer.py"", line 1150, in __call__
      outputs = call_fn(inputs, *args, **kwargs)
    File ""/Users/sak/Desktop/demo_crisis_mmd/crisis_mmd/lib/python3.10/site-packages/keras/src/utils/traceback_utils.py"", line 96, in error_handler
      return fn(*args, **kwargs)
    File ""/Users/sak/Desktop/demo_crisis_mmd/crisis_mmd/lib/python3.10/site-packages/keras/src/layers/core/embedding.py"", line 272, in call
      out = tf.nn.embedding_lookup(self.embeddings, inputs)
Node: 'model/embedding/embedding_lookup'
indices[0,7] = 194 is not in [0, 120)
	 [[{{node model/embedding/embedding_lookup}}]] [Op:__inference_predict_function_5943]","Traceback (most recent call last):
  File ""/Users/sak/Desktop/demo_crisis_mmd/dmd_inference_ensemble_batched.py"", line 125, in <module>
    preds, inf_time = ensemble_predict(models, text_input, image_input)
  File ""/Users/sak/Desktop/demo_crisis_mmd/dmd_inference_ensemble_batched.py"", line 88, in ensemble_predict
    preds = [model.predict([image, text], verbose=0) for model in models]
  File ""/Users/sak/Desktop/demo_crisis_mmd/dmd_inference_ensemble_batched.py"", line 88, in <listcomp>
    preds = [model.predict([image, text], verbose=0) for model in models]
  File ""/Users/sak/Desktop/demo_crisis_mmd/crisis_mmd/lib/python3.10/site-packages/keras/src/utils/traceback_utils.py"", line 70, in error_handler
    raise e.with_traceback(filtered_tb) from None
  File ""/Users/sak/Desktop/demo_crisis_mmd/crisis_mmd/lib/python3.10/site-packages/tensorflow/python/eager/execute.py"", line 53, in quick_execute
    tensors = pywrap_tfe.TFE_Py_Execute(ctx._handle, device_name, op_name,
tensorflow.python.framework.errors_impl.InvalidArgumentError: Graph execution error:

Detected at node 'model/embedding/embedding_lookup' defined at (most recent call last):
    File ""/Users/sak/Desktop/demo_crisis_mmd/dmd_inference_ensemble_batched.py"", line 125, in <module>
      preds, inf_time = ensemble_predict(models, text_input, image_input)
    File ""/Users/sak/Desktop/demo_crisis_mmd/dmd_inference_ensemble_batched.py"", line 88, in ensemble_predict
      preds = [model.predict([image, text], verbose=0) for model in models]
    File ""/Users/sak/Desktop/demo_crisis_mmd/dmd_inference_ensemble_batched.py"", line 88, in <listcomp>
      preds = [model.predict([image, text], verbose=0) for model in models]
    File ""/Users/sak/Desktop/demo_crisis_mmd/crisis_mmd/lib/python3.10/site-packages/keras/src/utils/traceback_utils.py"", line 65, in error_handler
      return fn(*args, **kwargs)
    File ""/Users/sak/Desktop/demo_crisis_mmd/crisis_mmd/lib/python3.10/site-packages/keras/src/engine/training.py"", line 2554, in predict
      tmp_batch_outputs = self.predict_function(iterator)
    File ""/Users/sak/Desktop/demo_crisis_mmd/crisis_mmd/lib/python3.10/site-packages/keras/src/engine/training.py"", line 2341, in predict_function
      return step_function(self, iterator)
    File ""/Users/sak/Desktop/demo_crisis_mmd/crisis_mmd/lib/python3.10/site-packages/keras/src/engine/training.py"", line 2327, in step_function
      outputs = model.distribute_strategy.run(run_step, args=(data,))
    File ""/Users/sak/Desktop/demo_crisis_mmd/crisis_mmd/lib/python3.10/site-packages/keras/src/engine/training.py"", line 2315, in run_step
      outputs = model.predict_step(data)
    File ""/Users/sak/Desktop/demo_crisis_mmd/crisis_mmd/lib/python3.10/site-packages/keras/src/engine/training.py"", line 2283, in predict_step
      return self(x, training=False)
    File ""/Users/sak/Desktop/demo_crisis_mmd/crisis_mmd/lib/python3.10/site-packages/keras/src/utils/traceback_utils.py"", line 65, in error_handler
      return fn(*args, **kwargs)
    File ""/Users/sak/Desktop/demo_crisis_mmd/crisis_mmd/lib/python3.10/site-packages/keras/src/engine/training.py"", line 569, in __call__
      return super().__call__(*args, **kwargs)
    File ""/Users/sak/Desktop/demo_crisis_mmd/crisis_mmd/lib/python3.10/site-packages/keras/src/utils/traceback_utils.py"", line 65, in error_handler
      return fn(*args, **kwargs)
    File ""/Users/sak/Desktop/demo_crisis_mmd/crisis_mmd/lib/python3.10/site-packages/keras/src/engine/base_layer.py"", line 1150, in __call__
      outputs = call_fn(inputs, *args, **kwargs)
    File ""/Users/sak/Desktop/demo_crisis_mmd/crisis_mmd/lib/python3.10/site-packages/keras/src/utils/traceback_utils.py"", line 96, in error_handler
      return fn(*args, **kwargs)
    File ""/Users/sak/Desktop/demo_crisis_mmd/crisis_mmd/lib/python3.10/site-packages/keras/src/engine/functional.py"", line 512, in call
      return self._run_internal_graph(inputs, training=training, mask=mask)
    File ""/Users/sak/Desktop/demo_crisis_mmd/crisis_mmd/lib/python3.10/site-packages/keras/src/engine/functional.py"", line 669, in _run_internal_graph
      outputs = node.layer(*args, **kwargs)
    File ""/Users/sak/Desktop/demo_crisis_mmd/crisis_mmd/lib/python3.10/site-packages/keras/src/utils/traceback_utils.py"", line 65, in error_handler
      return fn(*args, **kwargs)
    File ""/Users/sak/Desktop/demo_crisis_mmd/crisis_mmd/lib/python3.10/site-packages/keras/src/engine/base_layer.py"", line 1150, in __call__
      outputs = call_fn(inputs, *args, **kwargs)
    File ""/Users/sak/Desktop/demo_crisis_mmd/crisis_mmd/lib/python3.10/site-packages/keras/src/utils/traceback_utils.py"", line 96, in error_handler
      return fn(*args, **kwargs)
    File ""/Users/sak/Desktop/demo_crisis_mmd/crisis_mmd/lib/python3.10/site-packages/keras/src/layers/core/embedding.py"", line 272, in call
      out = tf.nn.embedding_lookup(self.embeddings, inputs)
Node: 'model/embedding/embedding_lookup'
indices[0,7] = 194 is not in [0, 120)
	 [[{{node model/embedding/embedding_lookup}}]] [Op:__inference_predict_function_5943]
"
4198,dmd/multimodal/non_damage/images/ad_2017-11-25_07-45-57.jpg,dmd/multimodal/non_damage/text/ad_2017-11-25_07-45-57.txt,"Graph execution error:

Detected at node 'model/embedding/embedding_lookup' defined at (most recent call last):
    File ""/Users/sak/Desktop/demo_crisis_mmd/dmd_inference_ensemble_batched.py"", line 125, in <module>
      preds, inf_time = ensemble_predict(models, text_input, image_input)
    File ""/Users/sak/Desktop/demo_crisis_mmd/dmd_inference_ensemble_batched.py"", line 88, in ensemble_predict
      preds = [model.predict([image, text], verbose=0) for model in models]
    File ""/Users/sak/Desktop/demo_crisis_mmd/dmd_inference_ensemble_batched.py"", line 88, in <listcomp>
      preds = [model.predict([image, text], verbose=0) for model in models]
    File ""/Users/sak/Desktop/demo_crisis_mmd/crisis_mmd/lib/python3.10/site-packages/keras/src/utils/traceback_utils.py"", line 65, in error_handler
      return fn(*args, **kwargs)
    File ""/Users/sak/Desktop/demo_crisis_mmd/crisis_mmd/lib/python3.10/site-packages/keras/src/engine/training.py"", line 2554, in predict
      tmp_batch_outputs = self.predict_function(iterator)
    File ""/Users/sak/Desktop/demo_crisis_mmd/crisis_mmd/lib/python3.10/site-packages/keras/src/engine/training.py"", line 2341, in predict_function
      return step_function(self, iterator)
    File ""/Users/sak/Desktop/demo_crisis_mmd/crisis_mmd/lib/python3.10/site-packages/keras/src/engine/training.py"", line 2327, in step_function
      outputs = model.distribute_strategy.run(run_step, args=(data,))
    File ""/Users/sak/Desktop/demo_crisis_mmd/crisis_mmd/lib/python3.10/site-packages/keras/src/engine/training.py"", line 2315, in run_step
      outputs = model.predict_step(data)
    File ""/Users/sak/Desktop/demo_crisis_mmd/crisis_mmd/lib/python3.10/site-packages/keras/src/engine/training.py"", line 2283, in predict_step
      return self(x, training=False)
    File ""/Users/sak/Desktop/demo_crisis_mmd/crisis_mmd/lib/python3.10/site-packages/keras/src/utils/traceback_utils.py"", line 65, in error_handler
      return fn(*args, **kwargs)
    File ""/Users/sak/Desktop/demo_crisis_mmd/crisis_mmd/lib/python3.10/site-packages/keras/src/engine/training.py"", line 569, in __call__
      return super().__call__(*args, **kwargs)
    File ""/Users/sak/Desktop/demo_crisis_mmd/crisis_mmd/lib/python3.10/site-packages/keras/src/utils/traceback_utils.py"", line 65, in error_handler
      return fn(*args, **kwargs)
    File ""/Users/sak/Desktop/demo_crisis_mmd/crisis_mmd/lib/python3.10/site-packages/keras/src/engine/base_layer.py"", line 1150, in __call__
      outputs = call_fn(inputs, *args, **kwargs)
    File ""/Users/sak/Desktop/demo_crisis_mmd/crisis_mmd/lib/python3.10/site-packages/keras/src/utils/traceback_utils.py"", line 96, in error_handler
      return fn(*args, **kwargs)
    File ""/Users/sak/Desktop/demo_crisis_mmd/crisis_mmd/lib/python3.10/site-packages/keras/src/engine/functional.py"", line 512, in call
      return self._run_internal_graph(inputs, training=training, mask=mask)
    File ""/Users/sak/Desktop/demo_crisis_mmd/crisis_mmd/lib/python3.10/site-packages/keras/src/engine/functional.py"", line 669, in _run_internal_graph
      outputs = node.layer(*args, **kwargs)
    File ""/Users/sak/Desktop/demo_crisis_mmd/crisis_mmd/lib/python3.10/site-packages/keras/src/utils/traceback_utils.py"", line 65, in error_handler
      return fn(*args, **kwargs)
    File ""/Users/sak/Desktop/demo_crisis_mmd/crisis_mmd/lib/python3.10/site-packages/keras/src/engine/base_layer.py"", line 1150, in __call__
      outputs = call_fn(inputs, *args, **kwargs)
    File ""/Users/sak/Desktop/demo_crisis_mmd/crisis_mmd/lib/python3.10/site-packages/keras/src/utils/traceback_utils.py"", line 96, in error_handler
      return fn(*args, **kwargs)
    File ""/Users/sak/Desktop/demo_crisis_mmd/crisis_mmd/lib/python3.10/site-packages/keras/src/layers/core/embedding.py"", line 272, in call
      out = tf.nn.embedding_lookup(self.embeddings, inputs)
Node: 'model/embedding/embedding_lookup'
indices[0,1] = 167 is not in [0, 120)
	 [[{{node model/embedding/embedding_lookup}}]] [Op:__inference_predict_function_5943]","Traceback (most recent call last):
  File ""/Users/sak/Desktop/demo_crisis_mmd/dmd_inference_ensemble_batched.py"", line 125, in <module>
    preds, inf_time = ensemble_predict(models, text_input, image_input)
  File ""/Users/sak/Desktop/demo_crisis_mmd/dmd_inference_ensemble_batched.py"", line 88, in ensemble_predict
    preds = [model.predict([image, text], verbose=0) for model in models]
  File ""/Users/sak/Desktop/demo_crisis_mmd/dmd_inference_ensemble_batched.py"", line 88, in <listcomp>
    preds = [model.predict([image, text], verbose=0) for model in models]
  File ""/Users/sak/Desktop/demo_crisis_mmd/crisis_mmd/lib/python3.10/site-packages/keras/src/utils/traceback_utils.py"", line 70, in error_handler
    raise e.with_traceback(filtered_tb) from None
  File ""/Users/sak/Desktop/demo_crisis_mmd/crisis_mmd/lib/python3.10/site-packages/tensorflow/python/eager/execute.py"", line 53, in quick_execute
    tensors = pywrap_tfe.TFE_Py_Execute(ctx._handle, device_name, op_name,
tensorflow.python.framework.errors_impl.InvalidArgumentError: Graph execution error:

Detected at node 'model/embedding/embedding_lookup' defined at (most recent call last):
    File ""/Users/sak/Desktop/demo_crisis_mmd/dmd_inference_ensemble_batched.py"", line 125, in <module>
      preds, inf_time = ensemble_predict(models, text_input, image_input)
    File ""/Users/sak/Desktop/demo_crisis_mmd/dmd_inference_ensemble_batched.py"", line 88, in ensemble_predict
      preds = [model.predict([image, text], verbose=0) for model in models]
    File ""/Users/sak/Desktop/demo_crisis_mmd/dmd_inference_ensemble_batched.py"", line 88, in <listcomp>
      preds = [model.predict([image, text], verbose=0) for model in models]
    File ""/Users/sak/Desktop/demo_crisis_mmd/crisis_mmd/lib/python3.10/site-packages/keras/src/utils/traceback_utils.py"", line 65, in error_handler
      return fn(*args, **kwargs)
    File ""/Users/sak/Desktop/demo_crisis_mmd/crisis_mmd/lib/python3.10/site-packages/keras/src/engine/training.py"", line 2554, in predict
      tmp_batch_outputs = self.predict_function(iterator)
    File ""/Users/sak/Desktop/demo_crisis_mmd/crisis_mmd/lib/python3.10/site-packages/keras/src/engine/training.py"", line 2341, in predict_function
      return step_function(self, iterator)
    File ""/Users/sak/Desktop/demo_crisis_mmd/crisis_mmd/lib/python3.10/site-packages/keras/src/engine/training.py"", line 2327, in step_function
      outputs = model.distribute_strategy.run(run_step, args=(data,))
    File ""/Users/sak/Desktop/demo_crisis_mmd/crisis_mmd/lib/python3.10/site-packages/keras/src/engine/training.py"", line 2315, in run_step
      outputs = model.predict_step(data)
    File ""/Users/sak/Desktop/demo_crisis_mmd/crisis_mmd/lib/python3.10/site-packages/keras/src/engine/training.py"", line 2283, in predict_step
      return self(x, training=False)
    File ""/Users/sak/Desktop/demo_crisis_mmd/crisis_mmd/lib/python3.10/site-packages/keras/src/utils/traceback_utils.py"", line 65, in error_handler
      return fn(*args, **kwargs)
    File ""/Users/sak/Desktop/demo_crisis_mmd/crisis_mmd/lib/python3.10/site-packages/keras/src/engine/training.py"", line 569, in __call__
      return super().__call__(*args, **kwargs)
    File ""/Users/sak/Desktop/demo_crisis_mmd/crisis_mmd/lib/python3.10/site-packages/keras/src/utils/traceback_utils.py"", line 65, in error_handler
      return fn(*args, **kwargs)
    File ""/Users/sak/Desktop/demo_crisis_mmd/crisis_mmd/lib/python3.10/site-packages/keras/src/engine/base_layer.py"", line 1150, in __call__
      outputs = call_fn(inputs, *args, **kwargs)
    File ""/Users/sak/Desktop/demo_crisis_mmd/crisis_mmd/lib/python3.10/site-packages/keras/src/utils/traceback_utils.py"", line 96, in error_handler
      return fn(*args, **kwargs)
    File ""/Users/sak/Desktop/demo_crisis_mmd/crisis_mmd/lib/python3.10/site-packages/keras/src/engine/functional.py"", line 512, in call
      return self._run_internal_graph(inputs, training=training, mask=mask)
    File ""/Users/sak/Desktop/demo_crisis_mmd/crisis_mmd/lib/python3.10/site-packages/keras/src/engine/functional.py"", line 669, in _run_internal_graph
      outputs = node.layer(*args, **kwargs)
    File ""/Users/sak/Desktop/demo_crisis_mmd/crisis_mmd/lib/python3.10/site-packages/keras/src/utils/traceback_utils.py"", line 65, in error_handler
      return fn(*args, **kwargs)
    File ""/Users/sak/Desktop/demo_crisis_mmd/crisis_mmd/lib/python3.10/site-packages/keras/src/engine/base_layer.py"", line 1150, in __call__
      outputs = call_fn(inputs, *args, **kwargs)
    File ""/Users/sak/Desktop/demo_crisis_mmd/crisis_mmd/lib/python3.10/site-packages/keras/src/utils/traceback_utils.py"", line 96, in error_handler
      return fn(*args, **kwargs)
    File ""/Users/sak/Desktop/demo_crisis_mmd/crisis_mmd/lib/python3.10/site-packages/keras/src/layers/core/embedding.py"", line 272, in call
      out = tf.nn.embedding_lookup(self.embeddings, inputs)
Node: 'model/embedding/embedding_lookup'
indices[0,1] = 167 is not in [0, 120)
	 [[{{node model/embedding/embedding_lookup}}]] [Op:__inference_predict_function_5943]
"
4280,dmd/multimodal/non_damage/images/ad_2017-11-25_03-34-06.jpg,dmd/multimodal/non_damage/text/ad_2017-11-25_03-34-06.txt,"Graph execution error:

Detected at node 'model/embedding/embedding_lookup' defined at (most recent call last):
    File ""/Users/sak/Desktop/demo_crisis_mmd/dmd_inference_ensemble_batched.py"", line 125, in <module>
      preds, inf_time = ensemble_predict(models, text_input, image_input)
    File ""/Users/sak/Desktop/demo_crisis_mmd/dmd_inference_ensemble_batched.py"", line 88, in ensemble_predict
      preds = [model.predict([image, text], verbose=0) for model in models]
    File ""/Users/sak/Desktop/demo_crisis_mmd/dmd_inference_ensemble_batched.py"", line 88, in <listcomp>
      preds = [model.predict([image, text], verbose=0) for model in models]
    File ""/Users/sak/Desktop/demo_crisis_mmd/crisis_mmd/lib/python3.10/site-packages/keras/src/utils/traceback_utils.py"", line 65, in error_handler
      return fn(*args, **kwargs)
    File ""/Users/sak/Desktop/demo_crisis_mmd/crisis_mmd/lib/python3.10/site-packages/keras/src/engine/training.py"", line 2554, in predict
      tmp_batch_outputs = self.predict_function(iterator)
    File ""/Users/sak/Desktop/demo_crisis_mmd/crisis_mmd/lib/python3.10/site-packages/keras/src/engine/training.py"", line 2341, in predict_function
      return step_function(self, iterator)
    File ""/Users/sak/Desktop/demo_crisis_mmd/crisis_mmd/lib/python3.10/site-packages/keras/src/engine/training.py"", line 2327, in step_function
      outputs = model.distribute_strategy.run(run_step, args=(data,))
    File ""/Users/sak/Desktop/demo_crisis_mmd/crisis_mmd/lib/python3.10/site-packages/keras/src/engine/training.py"", line 2315, in run_step
      outputs = model.predict_step(data)
    File ""/Users/sak/Desktop/demo_crisis_mmd/crisis_mmd/lib/python3.10/site-packages/keras/src/engine/training.py"", line 2283, in predict_step
      return self(x, training=False)
    File ""/Users/sak/Desktop/demo_crisis_mmd/crisis_mmd/lib/python3.10/site-packages/keras/src/utils/traceback_utils.py"", line 65, in error_handler
      return fn(*args, **kwargs)
    File ""/Users/sak/Desktop/demo_crisis_mmd/crisis_mmd/lib/python3.10/site-packages/keras/src/engine/training.py"", line 569, in __call__
      return super().__call__(*args, **kwargs)
    File ""/Users/sak/Desktop/demo_crisis_mmd/crisis_mmd/lib/python3.10/site-packages/keras/src/utils/traceback_utils.py"", line 65, in error_handler
      return fn(*args, **kwargs)
    File ""/Users/sak/Desktop/demo_crisis_mmd/crisis_mmd/lib/python3.10/site-packages/keras/src/engine/base_layer.py"", line 1150, in __call__
      outputs = call_fn(inputs, *args, **kwargs)
    File ""/Users/sak/Desktop/demo_crisis_mmd/crisis_mmd/lib/python3.10/site-packages/keras/src/utils/traceback_utils.py"", line 96, in error_handler
      return fn(*args, **kwargs)
    File ""/Users/sak/Desktop/demo_crisis_mmd/crisis_mmd/lib/python3.10/site-packages/keras/src/engine/functional.py"", line 512, in call
      return self._run_internal_graph(inputs, training=training, mask=mask)
    File ""/Users/sak/Desktop/demo_crisis_mmd/crisis_mmd/lib/python3.10/site-packages/keras/src/engine/functional.py"", line 669, in _run_internal_graph
      outputs = node.layer(*args, **kwargs)
    File ""/Users/sak/Desktop/demo_crisis_mmd/crisis_mmd/lib/python3.10/site-packages/keras/src/utils/traceback_utils.py"", line 65, in error_handler
      return fn(*args, **kwargs)
    File ""/Users/sak/Desktop/demo_crisis_mmd/crisis_mmd/lib/python3.10/site-packages/keras/src/engine/base_layer.py"", line 1150, in __call__
      outputs = call_fn(inputs, *args, **kwargs)
    File ""/Users/sak/Desktop/demo_crisis_mmd/crisis_mmd/lib/python3.10/site-packages/keras/src/utils/traceback_utils.py"", line 96, in error_handler
      return fn(*args, **kwargs)
    File ""/Users/sak/Desktop/demo_crisis_mmd/crisis_mmd/lib/python3.10/site-packages/keras/src/layers/core/embedding.py"", line 272, in call
      out = tf.nn.embedding_lookup(self.embeddings, inputs)
Node: 'model/embedding/embedding_lookup'
indices[0,21] = 167 is not in [0, 120)
	 [[{{node model/embedding/embedding_lookup}}]] [Op:__inference_predict_function_5943]","Traceback (most recent call last):
  File ""/Users/sak/Desktop/demo_crisis_mmd/dmd_inference_ensemble_batched.py"", line 125, in <module>
    preds, inf_time = ensemble_predict(models, text_input, image_input)
  File ""/Users/sak/Desktop/demo_crisis_mmd/dmd_inference_ensemble_batched.py"", line 88, in ensemble_predict
    preds = [model.predict([image, text], verbose=0) for model in models]
  File ""/Users/sak/Desktop/demo_crisis_mmd/dmd_inference_ensemble_batched.py"", line 88, in <listcomp>
    preds = [model.predict([image, text], verbose=0) for model in models]
  File ""/Users/sak/Desktop/demo_crisis_mmd/crisis_mmd/lib/python3.10/site-packages/keras/src/utils/traceback_utils.py"", line 70, in error_handler
    raise e.with_traceback(filtered_tb) from None
  File ""/Users/sak/Desktop/demo_crisis_mmd/crisis_mmd/lib/python3.10/site-packages/tensorflow/python/eager/execute.py"", line 53, in quick_execute
    tensors = pywrap_tfe.TFE_Py_Execute(ctx._handle, device_name, op_name,
tensorflow.python.framework.errors_impl.InvalidArgumentError: Graph execution error:

Detected at node 'model/embedding/embedding_lookup' defined at (most recent call last):
    File ""/Users/sak/Desktop/demo_crisis_mmd/dmd_inference_ensemble_batched.py"", line 125, in <module>
      preds, inf_time = ensemble_predict(models, text_input, image_input)
    File ""/Users/sak/Desktop/demo_crisis_mmd/dmd_inference_ensemble_batched.py"", line 88, in ensemble_predict
      preds = [model.predict([image, text], verbose=0) for model in models]
    File ""/Users/sak/Desktop/demo_crisis_mmd/dmd_inference_ensemble_batched.py"", line 88, in <listcomp>
      preds = [model.predict([image, text], verbose=0) for model in models]
    File ""/Users/sak/Desktop/demo_crisis_mmd/crisis_mmd/lib/python3.10/site-packages/keras/src/utils/traceback_utils.py"", line 65, in error_handler
      return fn(*args, **kwargs)
    File ""/Users/sak/Desktop/demo_crisis_mmd/crisis_mmd/lib/python3.10/site-packages/keras/src/engine/training.py"", line 2554, in predict
      tmp_batch_outputs = self.predict_function(iterator)
    File ""/Users/sak/Desktop/demo_crisis_mmd/crisis_mmd/lib/python3.10/site-packages/keras/src/engine/training.py"", line 2341, in predict_function
      return step_function(self, iterator)
    File ""/Users/sak/Desktop/demo_crisis_mmd/crisis_mmd/lib/python3.10/site-packages/keras/src/engine/training.py"", line 2327, in step_function
      outputs = model.distribute_strategy.run(run_step, args=(data,))
    File ""/Users/sak/Desktop/demo_crisis_mmd/crisis_mmd/lib/python3.10/site-packages/keras/src/engine/training.py"", line 2315, in run_step
      outputs = model.predict_step(data)
    File ""/Users/sak/Desktop/demo_crisis_mmd/crisis_mmd/lib/python3.10/site-packages/keras/src/engine/training.py"", line 2283, in predict_step
      return self(x, training=False)
    File ""/Users/sak/Desktop/demo_crisis_mmd/crisis_mmd/lib/python3.10/site-packages/keras/src/utils/traceback_utils.py"", line 65, in error_handler
      return fn(*args, **kwargs)
    File ""/Users/sak/Desktop/demo_crisis_mmd/crisis_mmd/lib/python3.10/site-packages/keras/src/engine/training.py"", line 569, in __call__
      return super().__call__(*args, **kwargs)
    File ""/Users/sak/Desktop/demo_crisis_mmd/crisis_mmd/lib/python3.10/site-packages/keras/src/utils/traceback_utils.py"", line 65, in error_handler
      return fn(*args, **kwargs)
    File ""/Users/sak/Desktop/demo_crisis_mmd/crisis_mmd/lib/python3.10/site-packages/keras/src/engine/base_layer.py"", line 1150, in __call__
      outputs = call_fn(inputs, *args, **kwargs)
    File ""/Users/sak/Desktop/demo_crisis_mmd/crisis_mmd/lib/python3.10/site-packages/keras/src/utils/traceback_utils.py"", line 96, in error_handler
      return fn(*args, **kwargs)
    File ""/Users/sak/Desktop/demo_crisis_mmd/crisis_mmd/lib/python3.10/site-packages/keras/src/engine/functional.py"", line 512, in call
      return self._run_internal_graph(inputs, training=training, mask=mask)
    File ""/Users/sak/Desktop/demo_crisis_mmd/crisis_mmd/lib/python3.10/site-packages/keras/src/engine/functional.py"", line 669, in _run_internal_graph
      outputs = node.layer(*args, **kwargs)
    File ""/Users/sak/Desktop/demo_crisis_mmd/crisis_mmd/lib/python3.10/site-packages/keras/src/utils/traceback_utils.py"", line 65, in error_handler
      return fn(*args, **kwargs)
    File ""/Users/sak/Desktop/demo_crisis_mmd/crisis_mmd/lib/python3.10/site-packages/keras/src/engine/base_layer.py"", line 1150, in __call__
      outputs = call_fn(inputs, *args, **kwargs)
    File ""/Users/sak/Desktop/demo_crisis_mmd/crisis_mmd/lib/python3.10/site-packages/keras/src/utils/traceback_utils.py"", line 96, in error_handler
      return fn(*args, **kwargs)
    File ""/Users/sak/Desktop/demo_crisis_mmd/crisis_mmd/lib/python3.10/site-packages/keras/src/layers/core/embedding.py"", line 272, in call
      out = tf.nn.embedding_lookup(self.embeddings, inputs)
Node: 'model/embedding/embedding_lookup'
indices[0,21] = 167 is not in [0, 120)
	 [[{{node model/embedding/embedding_lookup}}]] [Op:__inference_predict_function_5943]
"
4288,dmd/multimodal/non_damage/images/ad_2017-11-25_05-31-19.jpg,dmd/multimodal/non_damage/text/ad_2017-11-25_05-31-19.txt,"Graph execution error:

Detected at node 'model/embedding/embedding_lookup' defined at (most recent call last):
    File ""/Users/sak/Desktop/demo_crisis_mmd/dmd_inference_ensemble_batched.py"", line 125, in <module>
      preds, inf_time = ensemble_predict(models, text_input, image_input)
    File ""/Users/sak/Desktop/demo_crisis_mmd/dmd_inference_ensemble_batched.py"", line 88, in ensemble_predict
      preds = [model.predict([image, text], verbose=0) for model in models]
    File ""/Users/sak/Desktop/demo_crisis_mmd/dmd_inference_ensemble_batched.py"", line 88, in <listcomp>
      preds = [model.predict([image, text], verbose=0) for model in models]
    File ""/Users/sak/Desktop/demo_crisis_mmd/crisis_mmd/lib/python3.10/site-packages/keras/src/utils/traceback_utils.py"", line 65, in error_handler
      return fn(*args, **kwargs)
    File ""/Users/sak/Desktop/demo_crisis_mmd/crisis_mmd/lib/python3.10/site-packages/keras/src/engine/training.py"", line 2554, in predict
      tmp_batch_outputs = self.predict_function(iterator)
    File ""/Users/sak/Desktop/demo_crisis_mmd/crisis_mmd/lib/python3.10/site-packages/keras/src/engine/training.py"", line 2341, in predict_function
      return step_function(self, iterator)
    File ""/Users/sak/Desktop/demo_crisis_mmd/crisis_mmd/lib/python3.10/site-packages/keras/src/engine/training.py"", line 2327, in step_function
      outputs = model.distribute_strategy.run(run_step, args=(data,))
    File ""/Users/sak/Desktop/demo_crisis_mmd/crisis_mmd/lib/python3.10/site-packages/keras/src/engine/training.py"", line 2315, in run_step
      outputs = model.predict_step(data)
    File ""/Users/sak/Desktop/demo_crisis_mmd/crisis_mmd/lib/python3.10/site-packages/keras/src/engine/training.py"", line 2283, in predict_step
      return self(x, training=False)
    File ""/Users/sak/Desktop/demo_crisis_mmd/crisis_mmd/lib/python3.10/site-packages/keras/src/utils/traceback_utils.py"", line 65, in error_handler
      return fn(*args, **kwargs)
    File ""/Users/sak/Desktop/demo_crisis_mmd/crisis_mmd/lib/python3.10/site-packages/keras/src/engine/training.py"", line 569, in __call__
      return super().__call__(*args, **kwargs)
    File ""/Users/sak/Desktop/demo_crisis_mmd/crisis_mmd/lib/python3.10/site-packages/keras/src/utils/traceback_utils.py"", line 65, in error_handler
      return fn(*args, **kwargs)
    File ""/Users/sak/Desktop/demo_crisis_mmd/crisis_mmd/lib/python3.10/site-packages/keras/src/engine/base_layer.py"", line 1150, in __call__
      outputs = call_fn(inputs, *args, **kwargs)
    File ""/Users/sak/Desktop/demo_crisis_mmd/crisis_mmd/lib/python3.10/site-packages/keras/src/utils/traceback_utils.py"", line 96, in error_handler
      return fn(*args, **kwargs)
    File ""/Users/sak/Desktop/demo_crisis_mmd/crisis_mmd/lib/python3.10/site-packages/keras/src/engine/functional.py"", line 512, in call
      return self._run_internal_graph(inputs, training=training, mask=mask)
    File ""/Users/sak/Desktop/demo_crisis_mmd/crisis_mmd/lib/python3.10/site-packages/keras/src/engine/functional.py"", line 669, in _run_internal_graph
      outputs = node.layer(*args, **kwargs)
    File ""/Users/sak/Desktop/demo_crisis_mmd/crisis_mmd/lib/python3.10/site-packages/keras/src/utils/traceback_utils.py"", line 65, in error_handler
      return fn(*args, **kwargs)
    File ""/Users/sak/Desktop/demo_crisis_mmd/crisis_mmd/lib/python3.10/site-packages/keras/src/engine/base_layer.py"", line 1150, in __call__
      outputs = call_fn(inputs, *args, **kwargs)
    File ""/Users/sak/Desktop/demo_crisis_mmd/crisis_mmd/lib/python3.10/site-packages/keras/src/utils/traceback_utils.py"", line 96, in error_handler
      return fn(*args, **kwargs)
    File ""/Users/sak/Desktop/demo_crisis_mmd/crisis_mmd/lib/python3.10/site-packages/keras/src/layers/core/embedding.py"", line 272, in call
      out = tf.nn.embedding_lookup(self.embeddings, inputs)
Node: 'model/embedding/embedding_lookup'
indices[0,18] = 167 is not in [0, 120)
	 [[{{node model/embedding/embedding_lookup}}]] [Op:__inference_predict_function_5943]","Traceback (most recent call last):
  File ""/Users/sak/Desktop/demo_crisis_mmd/dmd_inference_ensemble_batched.py"", line 125, in <module>
    preds, inf_time = ensemble_predict(models, text_input, image_input)
  File ""/Users/sak/Desktop/demo_crisis_mmd/dmd_inference_ensemble_batched.py"", line 88, in ensemble_predict
    preds = [model.predict([image, text], verbose=0) for model in models]
  File ""/Users/sak/Desktop/demo_crisis_mmd/dmd_inference_ensemble_batched.py"", line 88, in <listcomp>
    preds = [model.predict([image, text], verbose=0) for model in models]
  File ""/Users/sak/Desktop/demo_crisis_mmd/crisis_mmd/lib/python3.10/site-packages/keras/src/utils/traceback_utils.py"", line 70, in error_handler
    raise e.with_traceback(filtered_tb) from None
  File ""/Users/sak/Desktop/demo_crisis_mmd/crisis_mmd/lib/python3.10/site-packages/tensorflow/python/eager/execute.py"", line 53, in quick_execute
    tensors = pywrap_tfe.TFE_Py_Execute(ctx._handle, device_name, op_name,
tensorflow.python.framework.errors_impl.InvalidArgumentError: Graph execution error:

Detected at node 'model/embedding/embedding_lookup' defined at (most recent call last):
    File ""/Users/sak/Desktop/demo_crisis_mmd/dmd_inference_ensemble_batched.py"", line 125, in <module>
      preds, inf_time = ensemble_predict(models, text_input, image_input)
    File ""/Users/sak/Desktop/demo_crisis_mmd/dmd_inference_ensemble_batched.py"", line 88, in ensemble_predict
      preds = [model.predict([image, text], verbose=0) for model in models]
    File ""/Users/sak/Desktop/demo_crisis_mmd/dmd_inference_ensemble_batched.py"", line 88, in <listcomp>
      preds = [model.predict([image, text], verbose=0) for model in models]
    File ""/Users/sak/Desktop/demo_crisis_mmd/crisis_mmd/lib/python3.10/site-packages/keras/src/utils/traceback_utils.py"", line 65, in error_handler
      return fn(*args, **kwargs)
    File ""/Users/sak/Desktop/demo_crisis_mmd/crisis_mmd/lib/python3.10/site-packages/keras/src/engine/training.py"", line 2554, in predict
      tmp_batch_outputs = self.predict_function(iterator)
    File ""/Users/sak/Desktop/demo_crisis_mmd/crisis_mmd/lib/python3.10/site-packages/keras/src/engine/training.py"", line 2341, in predict_function
      return step_function(self, iterator)
    File ""/Users/sak/Desktop/demo_crisis_mmd/crisis_mmd/lib/python3.10/site-packages/keras/src/engine/training.py"", line 2327, in step_function
      outputs = model.distribute_strategy.run(run_step, args=(data,))
    File ""/Users/sak/Desktop/demo_crisis_mmd/crisis_mmd/lib/python3.10/site-packages/keras/src/engine/training.py"", line 2315, in run_step
      outputs = model.predict_step(data)
    File ""/Users/sak/Desktop/demo_crisis_mmd/crisis_mmd/lib/python3.10/site-packages/keras/src/engine/training.py"", line 2283, in predict_step
      return self(x, training=False)
    File ""/Users/sak/Desktop/demo_crisis_mmd/crisis_mmd/lib/python3.10/site-packages/keras/src/utils/traceback_utils.py"", line 65, in error_handler
      return fn(*args, **kwargs)
    File ""/Users/sak/Desktop/demo_crisis_mmd/crisis_mmd/lib/python3.10/site-packages/keras/src/engine/training.py"", line 569, in __call__
      return super().__call__(*args, **kwargs)
    File ""/Users/sak/Desktop/demo_crisis_mmd/crisis_mmd/lib/python3.10/site-packages/keras/src/utils/traceback_utils.py"", line 65, in error_handler
      return fn(*args, **kwargs)
    File ""/Users/sak/Desktop/demo_crisis_mmd/crisis_mmd/lib/python3.10/site-packages/keras/src/engine/base_layer.py"", line 1150, in __call__
      outputs = call_fn(inputs, *args, **kwargs)
    File ""/Users/sak/Desktop/demo_crisis_mmd/crisis_mmd/lib/python3.10/site-packages/keras/src/utils/traceback_utils.py"", line 96, in error_handler
      return fn(*args, **kwargs)
    File ""/Users/sak/Desktop/demo_crisis_mmd/crisis_mmd/lib/python3.10/site-packages/keras/src/engine/functional.py"", line 512, in call
      return self._run_internal_graph(inputs, training=training, mask=mask)
    File ""/Users/sak/Desktop/demo_crisis_mmd/crisis_mmd/lib/python3.10/site-packages/keras/src/engine/functional.py"", line 669, in _run_internal_graph
      outputs = node.layer(*args, **kwargs)
    File ""/Users/sak/Desktop/demo_crisis_mmd/crisis_mmd/lib/python3.10/site-packages/keras/src/utils/traceback_utils.py"", line 65, in error_handler
      return fn(*args, **kwargs)
    File ""/Users/sak/Desktop/demo_crisis_mmd/crisis_mmd/lib/python3.10/site-packages/keras/src/engine/base_layer.py"", line 1150, in __call__
      outputs = call_fn(inputs, *args, **kwargs)
    File ""/Users/sak/Desktop/demo_crisis_mmd/crisis_mmd/lib/python3.10/site-packages/keras/src/utils/traceback_utils.py"", line 96, in error_handler
      return fn(*args, **kwargs)
    File ""/Users/sak/Desktop/demo_crisis_mmd/crisis_mmd/lib/python3.10/site-packages/keras/src/layers/core/embedding.py"", line 272, in call
      out = tf.nn.embedding_lookup(self.embeddings, inputs)
Node: 'model/embedding/embedding_lookup'
indices[0,18] = 167 is not in [0, 120)
	 [[{{node model/embedding/embedding_lookup}}]] [Op:__inference_predict_function_5943]
"
5619,dmd/multimodal/non_damage/images/ad_2017-11-25_05-22-24.jpg,dmd/multimodal/non_damage/text/ad_2017-11-25_05-22-24.txt,"Graph execution error:

Detected at node 'model/embedding/embedding_lookup' defined at (most recent call last):
    File ""/Users/sak/Desktop/demo_crisis_mmd/dmd_inference_ensemble_batched.py"", line 125, in <module>
      preds, inf_time = ensemble_predict(models, text_input, image_input)
    File ""/Users/sak/Desktop/demo_crisis_mmd/dmd_inference_ensemble_batched.py"", line 88, in ensemble_predict
      preds = [model.predict([image, text], verbose=0) for model in models]
    File ""/Users/sak/Desktop/demo_crisis_mmd/dmd_inference_ensemble_batched.py"", line 88, in <listcomp>
      preds = [model.predict([image, text], verbose=0) for model in models]
    File ""/Users/sak/Desktop/demo_crisis_mmd/crisis_mmd/lib/python3.10/site-packages/keras/src/utils/traceback_utils.py"", line 65, in error_handler
      return fn(*args, **kwargs)
    File ""/Users/sak/Desktop/demo_crisis_mmd/crisis_mmd/lib/python3.10/site-packages/keras/src/engine/training.py"", line 2554, in predict
      tmp_batch_outputs = self.predict_function(iterator)
    File ""/Users/sak/Desktop/demo_crisis_mmd/crisis_mmd/lib/python3.10/site-packages/keras/src/engine/training.py"", line 2341, in predict_function
      return step_function(self, iterator)
    File ""/Users/sak/Desktop/demo_crisis_mmd/crisis_mmd/lib/python3.10/site-packages/keras/src/engine/training.py"", line 2327, in step_function
      outputs = model.distribute_strategy.run(run_step, args=(data,))
    File ""/Users/sak/Desktop/demo_crisis_mmd/crisis_mmd/lib/python3.10/site-packages/keras/src/engine/training.py"", line 2315, in run_step
      outputs = model.predict_step(data)
    File ""/Users/sak/Desktop/demo_crisis_mmd/crisis_mmd/lib/python3.10/site-packages/keras/src/engine/training.py"", line 2283, in predict_step
      return self(x, training=False)
    File ""/Users/sak/Desktop/demo_crisis_mmd/crisis_mmd/lib/python3.10/site-packages/keras/src/utils/traceback_utils.py"", line 65, in error_handler
      return fn(*args, **kwargs)
    File ""/Users/sak/Desktop/demo_crisis_mmd/crisis_mmd/lib/python3.10/site-packages/keras/src/engine/training.py"", line 569, in __call__
      return super().__call__(*args, **kwargs)
    File ""/Users/sak/Desktop/demo_crisis_mmd/crisis_mmd/lib/python3.10/site-packages/keras/src/utils/traceback_utils.py"", line 65, in error_handler
      return fn(*args, **kwargs)
    File ""/Users/sak/Desktop/demo_crisis_mmd/crisis_mmd/lib/python3.10/site-packages/keras/src/engine/base_layer.py"", line 1150, in __call__
      outputs = call_fn(inputs, *args, **kwargs)
    File ""/Users/sak/Desktop/demo_crisis_mmd/crisis_mmd/lib/python3.10/site-packages/keras/src/utils/traceback_utils.py"", line 96, in error_handler
      return fn(*args, **kwargs)
    File ""/Users/sak/Desktop/demo_crisis_mmd/crisis_mmd/lib/python3.10/site-packages/keras/src/engine/functional.py"", line 512, in call
      return self._run_internal_graph(inputs, training=training, mask=mask)
    File ""/Users/sak/Desktop/demo_crisis_mmd/crisis_mmd/lib/python3.10/site-packages/keras/src/engine/functional.py"", line 669, in _run_internal_graph
      outputs = node.layer(*args, **kwargs)
    File ""/Users/sak/Desktop/demo_crisis_mmd/crisis_mmd/lib/python3.10/site-packages/keras/src/utils/traceback_utils.py"", line 65, in error_handler
      return fn(*args, **kwargs)
    File ""/Users/sak/Desktop/demo_crisis_mmd/crisis_mmd/lib/python3.10/site-packages/keras/src/engine/base_layer.py"", line 1150, in __call__
      outputs = call_fn(inputs, *args, **kwargs)
    File ""/Users/sak/Desktop/demo_crisis_mmd/crisis_mmd/lib/python3.10/site-packages/keras/src/utils/traceback_utils.py"", line 96, in error_handler
      return fn(*args, **kwargs)
    File ""/Users/sak/Desktop/demo_crisis_mmd/crisis_mmd/lib/python3.10/site-packages/keras/src/layers/core/embedding.py"", line 272, in call
      out = tf.nn.embedding_lookup(self.embeddings, inputs)
Node: 'model/embedding/embedding_lookup'
indices[0,17] = 167 is not in [0, 120)
	 [[{{node model/embedding/embedding_lookup}}]] [Op:__inference_predict_function_5943]","Traceback (most recent call last):
  File ""/Users/sak/Desktop/demo_crisis_mmd/dmd_inference_ensemble_batched.py"", line 125, in <module>
    preds, inf_time = ensemble_predict(models, text_input, image_input)
  File ""/Users/sak/Desktop/demo_crisis_mmd/dmd_inference_ensemble_batched.py"", line 88, in ensemble_predict
    preds = [model.predict([image, text], verbose=0) for model in models]
  File ""/Users/sak/Desktop/demo_crisis_mmd/dmd_inference_ensemble_batched.py"", line 88, in <listcomp>
    preds = [model.predict([image, text], verbose=0) for model in models]
  File ""/Users/sak/Desktop/demo_crisis_mmd/crisis_mmd/lib/python3.10/site-packages/keras/src/utils/traceback_utils.py"", line 70, in error_handler
    raise e.with_traceback(filtered_tb) from None
  File ""/Users/sak/Desktop/demo_crisis_mmd/crisis_mmd/lib/python3.10/site-packages/tensorflow/python/eager/execute.py"", line 53, in quick_execute
    tensors = pywrap_tfe.TFE_Py_Execute(ctx._handle, device_name, op_name,
tensorflow.python.framework.errors_impl.InvalidArgumentError: Graph execution error:

Detected at node 'model/embedding/embedding_lookup' defined at (most recent call last):
    File ""/Users/sak/Desktop/demo_crisis_mmd/dmd_inference_ensemble_batched.py"", line 125, in <module>
      preds, inf_time = ensemble_predict(models, text_input, image_input)
    File ""/Users/sak/Desktop/demo_crisis_mmd/dmd_inference_ensemble_batched.py"", line 88, in ensemble_predict
      preds = [model.predict([image, text], verbose=0) for model in models]
    File ""/Users/sak/Desktop/demo_crisis_mmd/dmd_inference_ensemble_batched.py"", line 88, in <listcomp>
      preds = [model.predict([image, text], verbose=0) for model in models]
    File ""/Users/sak/Desktop/demo_crisis_mmd/crisis_mmd/lib/python3.10/site-packages/keras/src/utils/traceback_utils.py"", line 65, in error_handler
      return fn(*args, **kwargs)
    File ""/Users/sak/Desktop/demo_crisis_mmd/crisis_mmd/lib/python3.10/site-packages/keras/src/engine/training.py"", line 2554, in predict
      tmp_batch_outputs = self.predict_function(iterator)
    File ""/Users/sak/Desktop/demo_crisis_mmd/crisis_mmd/lib/python3.10/site-packages/keras/src/engine/training.py"", line 2341, in predict_function
      return step_function(self, iterator)
    File ""/Users/sak/Desktop/demo_crisis_mmd/crisis_mmd/lib/python3.10/site-packages/keras/src/engine/training.py"", line 2327, in step_function
      outputs = model.distribute_strategy.run(run_step, args=(data,))
    File ""/Users/sak/Desktop/demo_crisis_mmd/crisis_mmd/lib/python3.10/site-packages/keras/src/engine/training.py"", line 2315, in run_step
      outputs = model.predict_step(data)
    File ""/Users/sak/Desktop/demo_crisis_mmd/crisis_mmd/lib/python3.10/site-packages/keras/src/engine/training.py"", line 2283, in predict_step
      return self(x, training=False)
    File ""/Users/sak/Desktop/demo_crisis_mmd/crisis_mmd/lib/python3.10/site-packages/keras/src/utils/traceback_utils.py"", line 65, in error_handler
      return fn(*args, **kwargs)
    File ""/Users/sak/Desktop/demo_crisis_mmd/crisis_mmd/lib/python3.10/site-packages/keras/src/engine/training.py"", line 569, in __call__
      return super().__call__(*args, **kwargs)
    File ""/Users/sak/Desktop/demo_crisis_mmd/crisis_mmd/lib/python3.10/site-packages/keras/src/utils/traceback_utils.py"", line 65, in error_handler
      return fn(*args, **kwargs)
    File ""/Users/sak/Desktop/demo_crisis_mmd/crisis_mmd/lib/python3.10/site-packages/keras/src/engine/base_layer.py"", line 1150, in __call__
      outputs = call_fn(inputs, *args, **kwargs)
    File ""/Users/sak/Desktop/demo_crisis_mmd/crisis_mmd/lib/python3.10/site-packages/keras/src/utils/traceback_utils.py"", line 96, in error_handler
      return fn(*args, **kwargs)
    File ""/Users/sak/Desktop/demo_crisis_mmd/crisis_mmd/lib/python3.10/site-packages/keras/src/engine/functional.py"", line 512, in call
      return self._run_internal_graph(inputs, training=training, mask=mask)
    File ""/Users/sak/Desktop/demo_crisis_mmd/crisis_mmd/lib/python3.10/site-packages/keras/src/engine/functional.py"", line 669, in _run_internal_graph
      outputs = node.layer(*args, **kwargs)
    File ""/Users/sak/Desktop/demo_crisis_mmd/crisis_mmd/lib/python3.10/site-packages/keras/src/utils/traceback_utils.py"", line 65, in error_handler
      return fn(*args, **kwargs)
    File ""/Users/sak/Desktop/demo_crisis_mmd/crisis_mmd/lib/python3.10/site-packages/keras/src/engine/base_layer.py"", line 1150, in __call__
      outputs = call_fn(inputs, *args, **kwargs)
    File ""/Users/sak/Desktop/demo_crisis_mmd/crisis_mmd/lib/python3.10/site-packages/keras/src/utils/traceback_utils.py"", line 96, in error_handler
      return fn(*args, **kwargs)
    File ""/Users/sak/Desktop/demo_crisis_mmd/crisis_mmd/lib/python3.10/site-packages/keras/src/layers/core/embedding.py"", line 272, in call
      out = tf.nn.embedding_lookup(self.embeddings, inputs)
Node: 'model/embedding/embedding_lookup'
indices[0,17] = 167 is not in [0, 120)
	 [[{{node model/embedding/embedding_lookup}}]] [Op:__inference_predict_function_5943]
"
5786,dmd/multimodal/non_damage/images/ad_2017-11-25_03-25-01.jpg,dmd/multimodal/non_damage/text/ad_2017-11-25_03-25-01.txt,"Graph execution error:

Detected at node 'model/embedding/embedding_lookup' defined at (most recent call last):
    File ""/Users/sak/Desktop/demo_crisis_mmd/dmd_inference_ensemble_batched.py"", line 125, in <module>
      preds, inf_time = ensemble_predict(models, text_input, image_input)
    File ""/Users/sak/Desktop/demo_crisis_mmd/dmd_inference_ensemble_batched.py"", line 88, in ensemble_predict
      preds = [model.predict([image, text], verbose=0) for model in models]
    File ""/Users/sak/Desktop/demo_crisis_mmd/dmd_inference_ensemble_batched.py"", line 88, in <listcomp>
      preds = [model.predict([image, text], verbose=0) for model in models]
    File ""/Users/sak/Desktop/demo_crisis_mmd/crisis_mmd/lib/python3.10/site-packages/keras/src/utils/traceback_utils.py"", line 65, in error_handler
      return fn(*args, **kwargs)
    File ""/Users/sak/Desktop/demo_crisis_mmd/crisis_mmd/lib/python3.10/site-packages/keras/src/engine/training.py"", line 2554, in predict
      tmp_batch_outputs = self.predict_function(iterator)
    File ""/Users/sak/Desktop/demo_crisis_mmd/crisis_mmd/lib/python3.10/site-packages/keras/src/engine/training.py"", line 2341, in predict_function
      return step_function(self, iterator)
    File ""/Users/sak/Desktop/demo_crisis_mmd/crisis_mmd/lib/python3.10/site-packages/keras/src/engine/training.py"", line 2327, in step_function
      outputs = model.distribute_strategy.run(run_step, args=(data,))
    File ""/Users/sak/Desktop/demo_crisis_mmd/crisis_mmd/lib/python3.10/site-packages/keras/src/engine/training.py"", line 2315, in run_step
      outputs = model.predict_step(data)
    File ""/Users/sak/Desktop/demo_crisis_mmd/crisis_mmd/lib/python3.10/site-packages/keras/src/engine/training.py"", line 2283, in predict_step
      return self(x, training=False)
    File ""/Users/sak/Desktop/demo_crisis_mmd/crisis_mmd/lib/python3.10/site-packages/keras/src/utils/traceback_utils.py"", line 65, in error_handler
      return fn(*args, **kwargs)
    File ""/Users/sak/Desktop/demo_crisis_mmd/crisis_mmd/lib/python3.10/site-packages/keras/src/engine/training.py"", line 569, in __call__
      return super().__call__(*args, **kwargs)
    File ""/Users/sak/Desktop/demo_crisis_mmd/crisis_mmd/lib/python3.10/site-packages/keras/src/utils/traceback_utils.py"", line 65, in error_handler
      return fn(*args, **kwargs)
    File ""/Users/sak/Desktop/demo_crisis_mmd/crisis_mmd/lib/python3.10/site-packages/keras/src/engine/base_layer.py"", line 1150, in __call__
      outputs = call_fn(inputs, *args, **kwargs)
    File ""/Users/sak/Desktop/demo_crisis_mmd/crisis_mmd/lib/python3.10/site-packages/keras/src/utils/traceback_utils.py"", line 96, in error_handler
      return fn(*args, **kwargs)
    File ""/Users/sak/Desktop/demo_crisis_mmd/crisis_mmd/lib/python3.10/site-packages/keras/src/engine/functional.py"", line 512, in call
      return self._run_internal_graph(inputs, training=training, mask=mask)
    File ""/Users/sak/Desktop/demo_crisis_mmd/crisis_mmd/lib/python3.10/site-packages/keras/src/engine/functional.py"", line 669, in _run_internal_graph
      outputs = node.layer(*args, **kwargs)
    File ""/Users/sak/Desktop/demo_crisis_mmd/crisis_mmd/lib/python3.10/site-packages/keras/src/utils/traceback_utils.py"", line 65, in error_handler
      return fn(*args, **kwargs)
    File ""/Users/sak/Desktop/demo_crisis_mmd/crisis_mmd/lib/python3.10/site-packages/keras/src/engine/base_layer.py"", line 1150, in __call__
      outputs = call_fn(inputs, *args, **kwargs)
    File ""/Users/sak/Desktop/demo_crisis_mmd/crisis_mmd/lib/python3.10/site-packages/keras/src/utils/traceback_utils.py"", line 96, in error_handler
      return fn(*args, **kwargs)
    File ""/Users/sak/Desktop/demo_crisis_mmd/crisis_mmd/lib/python3.10/site-packages/keras/src/layers/core/embedding.py"", line 272, in call
      out = tf.nn.embedding_lookup(self.embeddings, inputs)
Node: 'model/embedding/embedding_lookup'
indices[0,9] = 167 is not in [0, 120)
	 [[{{node model/embedding/embedding_lookup}}]] [Op:__inference_predict_function_5943]","Traceback (most recent call last):
  File ""/Users/sak/Desktop/demo_crisis_mmd/dmd_inference_ensemble_batched.py"", line 125, in <module>
    preds, inf_time = ensemble_predict(models, text_input, image_input)
  File ""/Users/sak/Desktop/demo_crisis_mmd/dmd_inference_ensemble_batched.py"", line 88, in ensemble_predict
    preds = [model.predict([image, text], verbose=0) for model in models]
  File ""/Users/sak/Desktop/demo_crisis_mmd/dmd_inference_ensemble_batched.py"", line 88, in <listcomp>
    preds = [model.predict([image, text], verbose=0) for model in models]
  File ""/Users/sak/Desktop/demo_crisis_mmd/crisis_mmd/lib/python3.10/site-packages/keras/src/utils/traceback_utils.py"", line 70, in error_handler
    raise e.with_traceback(filtered_tb) from None
  File ""/Users/sak/Desktop/demo_crisis_mmd/crisis_mmd/lib/python3.10/site-packages/tensorflow/python/eager/execute.py"", line 53, in quick_execute
    tensors = pywrap_tfe.TFE_Py_Execute(ctx._handle, device_name, op_name,
tensorflow.python.framework.errors_impl.InvalidArgumentError: Graph execution error:

Detected at node 'model/embedding/embedding_lookup' defined at (most recent call last):
    File ""/Users/sak/Desktop/demo_crisis_mmd/dmd_inference_ensemble_batched.py"", line 125, in <module>
      preds, inf_time = ensemble_predict(models, text_input, image_input)
    File ""/Users/sak/Desktop/demo_crisis_mmd/dmd_inference_ensemble_batched.py"", line 88, in ensemble_predict
      preds = [model.predict([image, text], verbose=0) for model in models]
    File ""/Users/sak/Desktop/demo_crisis_mmd/dmd_inference_ensemble_batched.py"", line 88, in <listcomp>
      preds = [model.predict([image, text], verbose=0) for model in models]
    File ""/Users/sak/Desktop/demo_crisis_mmd/crisis_mmd/lib/python3.10/site-packages/keras/src/utils/traceback_utils.py"", line 65, in error_handler
      return fn(*args, **kwargs)
    File ""/Users/sak/Desktop/demo_crisis_mmd/crisis_mmd/lib/python3.10/site-packages/keras/src/engine/training.py"", line 2554, in predict
      tmp_batch_outputs = self.predict_function(iterator)
    File ""/Users/sak/Desktop/demo_crisis_mmd/crisis_mmd/lib/python3.10/site-packages/keras/src/engine/training.py"", line 2341, in predict_function
      return step_function(self, iterator)
    File ""/Users/sak/Desktop/demo_crisis_mmd/crisis_mmd/lib/python3.10/site-packages/keras/src/engine/training.py"", line 2327, in step_function
      outputs = model.distribute_strategy.run(run_step, args=(data,))
    File ""/Users/sak/Desktop/demo_crisis_mmd/crisis_mmd/lib/python3.10/site-packages/keras/src/engine/training.py"", line 2315, in run_step
      outputs = model.predict_step(data)
    File ""/Users/sak/Desktop/demo_crisis_mmd/crisis_mmd/lib/python3.10/site-packages/keras/src/engine/training.py"", line 2283, in predict_step
      return self(x, training=False)
    File ""/Users/sak/Desktop/demo_crisis_mmd/crisis_mmd/lib/python3.10/site-packages/keras/src/utils/traceback_utils.py"", line 65, in error_handler
      return fn(*args, **kwargs)
    File ""/Users/sak/Desktop/demo_crisis_mmd/crisis_mmd/lib/python3.10/site-packages/keras/src/engine/training.py"", line 569, in __call__
      return super().__call__(*args, **kwargs)
    File ""/Users/sak/Desktop/demo_crisis_mmd/crisis_mmd/lib/python3.10/site-packages/keras/src/utils/traceback_utils.py"", line 65, in error_handler
      return fn(*args, **kwargs)
    File ""/Users/sak/Desktop/demo_crisis_mmd/crisis_mmd/lib/python3.10/site-packages/keras/src/engine/base_layer.py"", line 1150, in __call__
      outputs = call_fn(inputs, *args, **kwargs)
    File ""/Users/sak/Desktop/demo_crisis_mmd/crisis_mmd/lib/python3.10/site-packages/keras/src/utils/traceback_utils.py"", line 96, in error_handler
      return fn(*args, **kwargs)
    File ""/Users/sak/Desktop/demo_crisis_mmd/crisis_mmd/lib/python3.10/site-packages/keras/src/engine/functional.py"", line 512, in call
      return self._run_internal_graph(inputs, training=training, mask=mask)
    File ""/Users/sak/Desktop/demo_crisis_mmd/crisis_mmd/lib/python3.10/site-packages/keras/src/engine/functional.py"", line 669, in _run_internal_graph
      outputs = node.layer(*args, **kwargs)
    File ""/Users/sak/Desktop/demo_crisis_mmd/crisis_mmd/lib/python3.10/site-packages/keras/src/utils/traceback_utils.py"", line 65, in error_handler
      return fn(*args, **kwargs)
    File ""/Users/sak/Desktop/demo_crisis_mmd/crisis_mmd/lib/python3.10/site-packages/keras/src/engine/base_layer.py"", line 1150, in __call__
      outputs = call_fn(inputs, *args, **kwargs)
    File ""/Users/sak/Desktop/demo_crisis_mmd/crisis_mmd/lib/python3.10/site-packages/keras/src/utils/traceback_utils.py"", line 96, in error_handler
      return fn(*args, **kwargs)
    File ""/Users/sak/Desktop/demo_crisis_mmd/crisis_mmd/lib/python3.10/site-packages/keras/src/layers/core/embedding.py"", line 272, in call
      out = tf.nn.embedding_lookup(self.embeddings, inputs)
Node: 'model/embedding/embedding_lookup'
indices[0,9] = 167 is not in [0, 120)
	 [[{{node model/embedding/embedding_lookup}}]] [Op:__inference_predict_function_5943]
"
